Workbook

Sheet 可视化看板

Sheet 数据统计
B1: 注：填充色为浅黄色的单元格需要手动查找数据填充，其余数据从MSSP平台导出底数据后覆盖子表内容，再更新单元格L1和M1自动按照统计周期计算结果； | H1: 当前时间 | I1: =TODAY() -> 46113 | K1: 统计周期 | L1: 45870 | M1: 46098
B3: P5 | C3: 边界下一代防火墙AF | D3: 10
B4: 左侧接入组件数量 | C4: 全流量威胁检测与分析组STA | D4: 5
C5: 端点安全防护软件EDR | D5: 104
C6: 漏洞扫描组件TSS | D6: 1
C7: 第三方安全设备 | D7: 0
B8: P7 | C8: Q1 | D8: 2025/8/1～2025/10/30 | E8: Q2 | F8: 2025/11/1～2026/1/31 | G8: Q3 | H8: 2026/2/1～2026/4/30 | I8: Q4 | J8: 2026/5/1～2026/7/31
C9: 《项目启动会PPT》 | D9: 1 | F9: 《安全运营报告》--周报 | G9: =IF(M1-L1>0,INT((M1-L1)/7),"") -> 32
B10: 交付进度与交付物数量 | C10: 《首次分析与处置报告》 | D10: 1 | F10: 《综合分析报告》--月报 | G10: =IF(M1-L1>0,INT((M1-L1)/30),"") -> 7
C11: 《漏洞管理举证报告》 | D11: =IF(M1-L1>0,INT((M1-L1)/91),"") -> 2 | F11: 《安全运营报告》--季报 | G11: =IF(M1-L1>0,INT((M1-L1)/91),"") -> 2
C12: 《漏洞清单》 | D12: =IF(M1-L1>0,INT((M1-L1)/91),"") -> 2
C13: 《服务资产表》 | D13: 1 | F13: 《重要节假日网络安全保障工作简报》 | G13: =COUNTIFS(F103:F109,"<>") -> 4
C14: 《事件跟踪表》 | D14: =IF(M1-L1>0,INT((M1-L1)/30),"") -> 7
C15: 《应急响应报告》 | D15: 0
C16: 《暴露面梳理报告》 | D16: 1
F17: 《网络安全态势半月刊》+最新威胁情报 | G17: =COUNTIFS(事件表!A:A,"最新威胁") -> 109
F18: 《钓鱼场景安全意识海报》 | G18: 0
B20: P8 | C20: 网络安全事故数 | D20: 主动保护 | E20: 通报数 | F20: 通报问题闭环率 | G20: 事件数 | H20: 事件闭环率 | I20: 事件平均遏制时间
D21: 7*24 | E21: 0 | F21: 1 | G21: =COUNTIFS(事件表!A:A,"*事件*",事件表!B:B,">="&L1,事件表!B:B,"<="&M1) -> 26 | H21: 1 | I21: =AVERAGEIFS(事件表!BB:BB,事件表!BB:BB,"<>",事件表!A:A,"*事件*") -> 13.984167
B22: 左侧接入组件数量 | C22: 边界下一代防火墙AF | D22: 10 | E22: 中部 | F22: 安全日志数量 | G22: 4356578 | H22: 右侧 | I22: MSS服务内风险资产数 | J22: 118 | K22: AF防护路径覆盖率 | L22: 1
C23: 全流量威胁检测与分析组STA | D23: 5 | E23: XDR总览统计数据 | F23: 日志到告警消减率 | G23: =1-G24/G22 -> 0.97880469 | H23: MSS服务内风险资产数（XDR） | I23: 服务内告警数 | J23: 16199 | K23: 探针流量监测覆盖率 | L23: 1
C24: 端点安全防护软件EDR | D24: 104 | F24: 安全告警数量 | G24: 92339 | I24: 服务内事件数 | J24: 10248 | K24: AES安装覆盖率 | L24: 1
C25: 漏洞扫描组件TSS | D25: 1 | F25: 告警消减率 | G25: =1-G26/G24 -> 0.85391871 | I25: 服务内处置率 | J25: 1 | K25: 告警自动分析比例 | L25: =COUNTIFS(告警表!E:E,"*自动*")/(COUNTA(告警表!E:E)-1) -> 0.39203016
C26: 第三方安全设备 | D26: 0 | F26: 安全事件数 | G26: 13489 | I26: 平均响应时长 | J26: =AVERAGEIFS(事件表!BA:BA,事件表!BA:BA,"<>",事件表!A:A,"*事件*") -> 8.4496154 | K26: 告警人工分析比例 | L26: =(COUNTIFS(告警表!E:E,"已驳回")+COUNTIFS(告警表!E:E,"已加白")+COUNTIFS(告警表!E:E,"已完成"))/(COUNTA(告警表!E:E)-1) -> 0.60096931
F27: 风险资产数 | G27: 185 | H27: MSS服务外风险资产数（XDR） | I27: MSS服务内风险资产数 | J27: =G27-J22 -> 67
B28: 保护对象 | C28: 业务系统数 | D28: {=COUNTA(_xlfn.UNIQUE(资产表!$B$2:$B$20000))} -> 155 | I28: 服务外告警数 | J28: =G24-J23-16199 -> 59941
C29: 服务器资产数 | D29: =COUNTIFS(资产表!F:F,"服务器") -> 160 | I29: 服务外事件数 | J29: =G26-J24 -> 3241
C30: PC资产数 | D30: =COUNTIFS(资产表!F:F,"终端") -> 950 | I30: 服务外处置率 | J30: 1
I31: 平均响应时长 | J31: 312.33
B33: P9 | C33: 高危可利用漏洞防护率 | D33: 告警研判率 | E33: 告警平均响应时间 | F33: 威胁实时遏制率
C34: =D38/D43 -> 0.028571429 | D34: 1 | E34: =AVERAGEIFS(事件表!BA:BA,事件表!BA:BA,"<>",事件表!A:A,"*事件*") -> 8.4496154 | F34: 1
B35: 防护 | C35: AF外部攻击拦截数 | D35: 24401 | E35: 监测 | F35: XDR安全日志数量 | G35: =G22 -> 4356578
C36: EDR防护端点风险数 | D36: 185 | F36: XDR安全告警总数 | G36: =G24 -> 92339
C37: 策略检查与优化次数 | D37: 2 | F37: XDR安全事件数 | G37: =G26 -> 13489
C38: 高危可利用漏洞防护数 | D38: =COUNTIFS(资产漏洞表!E:E,"高危",资产漏洞表!F:F,"是",资产漏洞表!P:P,"已防护") -> 1 | F38: MSS通告事件数 | G38: =COUNTIFS(事件表!A:A,"*事件*",事件表!B:B,">="&L1,事件表!B:B,"<="&M1) -> 26
B39: 识别 | C39: 暴露面扫描次数 | D39: 1 | F39: MSS事件平均推送时长 | G39: =AVERAGEIFS(事件表!BA:BA,事件表!BA:BA,"<>",事件表!AW:AW,"已通告",事件表!A:A,"*事件*") -> 13.984167
C40: 资产和漏洞扫描次数 | D40: 2 | E40: 响应 | F40: XDR自动化处置事件数 | G40: 0
C41: 服务资产数 | D41: =COUNTIFS(资产表!F:F,"服务器") -> 160 | F41: MSS处置事件数 | G41: =COUNTIFS(事件表!A:A,"*事件*",事件表!B:B,">="&L1,事件表!B:B,"<="&M1,事件表!I:I,"已闭环") -> 22
C42: PC资产数 | D42: =COUNTIFS(资产表!F:F,"终端") -> 950 | F42: 应急处置事件数 | G42: 0
C43: 高危可利用漏洞数 | D43: =COUNTIFS(资产漏洞表!E:E,"高危",资产漏洞表!F:F,"是") -> 35 | F43: 事件平均遏制时间 | G43: =I21 -> 13.984167
...

Sheet 运营机制
B2: 风险管理
B3: 类别 | C3: 子类别 | D3: 服务执行机制 | E3: 用户方配合事项 | F3: 执行标准
B4: 互联网暴露面 | C4: 暴露面分析 | D4: 首次全面梳理 常态化监测扫描，每周轮询扫描一次 | E4: 确认暴露面是否为业务需要，对不需要的暴露面做访问权限收敛 | F4: 每季度/次
C5: 攻击面分析 | D5: 首次全面梳理外部攻击面及暴露面弱点 常态化监测扫描，每两周周轮询扫描一次 | E5: 对外部暴露面存在的业务弱点进行修复加固 | F5: 每半年/次
C6: 敏感数据泄露监测 | D6: 采用网络监测手段实时爬取暗网等平台是否存在单位相关的关键字数据信息，检测到后实时告警推送预警 | E6: 对异常数据外泄采取应对措施，降低影响 | F6: 7*24实时预警
B7: 漏洞管理 | C7: 互联网资产漏洞 | D7: 高危可利用：每季度针对服务器操作系统和应用程序执行一次漏洞扫描，验证漏洞的利用危害和业务影响 | E7: AF防护，针对AF无法防护的需要用户业务侧修复漏洞； 分发漏洞工单到业务系统维护方，开展漏洞修复和闭环跟进 | F7: 每季度/次
D8: 低可利用漏洞：每季度针对服务器操作系统和应用程序执行一次漏洞扫描，整理漏洞优先级 | E8: 针对有条件修复的漏洞定期进行补丁修复；修改系统配置或访问权限降低漏洞被利用的风险 | F8: 每季度/次
C9: 内网资产漏洞 | D9: 高危可利用：每季度针对服务器操作系统和应用程序执行一次漏洞扫描，整理漏洞优先级 | E9: AF防护，针对AF无法防护的需要用户业务侧修复漏洞； 分发漏洞工单到业务系统维护方，开展漏洞修复和闭环跟进 | F9: 每季度/次
D10: 低可利用漏洞：每季度针对服务器操作系统和应用程序执行一次漏洞扫描，整理漏洞优先级 | E10: 针对有条件修复的漏洞定期进行补丁修复；修改系统配置或访问权限降低漏洞被利用的风险 | F10: 每季度/次
B11: 业务弱点 | C11: 管理员弱密码 | D11: 主动探测：定期TSS扫描； 被动监测：实时推送工单，及时修改密码加固 | E11: 对发现的弱密码进行修改，制定/优化应用系统密码规则 | F11: 7*24实时预警
C12: 互联网系统弱密码 | D12: 被动监测：通过访问流量监测，发现后试试告警，通告用户方可及时修改强密码及密码规则； 主动探测：每季度执行一次互联网弱密码扫描 | E12: 对发现的弱密码进行修改，制定/优化应用系统密码规则 | F12: 7*24实时预警
C13: 内网普通用户弱密码 | D13: 被动监测：通过访问流量监测，发现后试试告警，通告用户方可及时修改强密码及密码规则； | E13: 对发现的弱密码进行修改，制定/优化应用系统密码规则 | F13: 每周/次
B14: 威胁运营
C15: 重大威胁 | D15: 定义：攻击者对内网发起的有组织，有预谋的持续性网络攻击（如 APT、新型威胁等） 7*24小时持续监测，发现有效威胁实时响应，遏制影响； | E15: 如发生业务行为命中安全规则被判定为攻击行为，封堵了源IP后造成业务访问异常时，反馈至服务群，解除封锁 | F15: 7*24实时处置
C16: 一般威胁 | D16: 定义：攻击者发起网络安全攻击，但是对业务未造成任何影响 7*24小时持续监测，发现有效威胁实时响应，遏制影响； | E16: 如发生业务行为命中安全规则被判定为攻击行为，封堵了源IP后造成业务访问异常时，反馈至服务群，解除封锁 | F16: 7*24实时处置
C17: 威胁预防 | D17: 定期开展安全设备策略/规则库检查，确保安全基础设施有效运行 | E17: 对存在风险的安全策略配合追溯原因和评估改进策略的可行性 | F17: 每月/次
B19: 闭环管理
B20: ①抑制：限制攻击或破坏涉及的范围，降低潜在的损失 ②调查：充足的举证信息 ③溯源：详细完整的入侵路径 ④处置：已发现问题的解决 ⑤加固：杜绝问题再次发生 | J20: 事件/告警分级定义标准
B21: 事件类型 | C21: 判断特征 | D21: 事件定级 | E21: 响应与闭环预案 | J21: 威胁及事件等级 | K21: 等级描述 | L21: 等级示例 | M21: SLA要求 | N21: 闭环要求
B22: 网络攻击 | C22: 攻击成功（例：Webshell上传成功） | D22: 重大事件 | E22: 抑制：联动AF封堵攻击源IP、隔离主机可疑进程或被上传的文件； 调查：关联日志分析攻击影响范围，对入侵成功的主机上机排查攻击动作痕迹和残余风险； 溯源：上机排查主机日志，结合流量日志还原攻击路径，找到入侵源头 处置：清除主机恶意文件/进程，恢复主机网络权限； 加固：针对入侵源头利用的漏洞点修复加固，加强安全策略配置 | J22: 重大事故 （对标国家标准I级事件） | K22: 因安全事件造成单位网络较大面积中断或主营业务系统较大面积瘫痪，影响系统重要客户的正常业务工作、对单位造成重大经济损失的或产生较严重不良社会影响： 1、网络较大面积中断：因网络中断，造成单位内半数以上部门不能正常使用一个及以上主营业务系统，持续时间超过 12 小时以上； 2、主营业务系统较大面积瘫痪：因系统主要功能不可用，造成单位内半数以上部门不能正常使用一个及以上主营业务系统，系统瘫痪时间 12 个小时以上。 | L22: 1、网络攻击类 外部攻击成功（webshell后门上传/远程命令执行/反序列化命令执行/远程漏洞利用成功等）且造成业务中断或关键业务数据丢失，影响重大的 2、病毒木马类 如加密勒索软件/webshell后门/黑链/主机存在恶意命令执行等事件发生，对业务连续性造成恶劣影响或产生勒索赔偿等重大损失的 | M22: 启用应急响应机制，工作时间15分钟，非工作时间30分钟之内云端专家进行响应，默认由专家团队进行远程协助解决，如远程无法解决的则采用最快的交通工具，省会2小时内上门处置，省内8小时内上门处置。 | N22: 抑制-->调查-->溯源-->处置-->加固
C23: 攻击失败（例：外网主机对内网主机发起一对多攻击） | D23: 重大威胁 | E23: 抑制（处置）：联动AF封堵攻击源IP | J23: 重大事件 （对标国家标准II级和III级事件） | K23: 因安全事件造成单位主营业务系统中断、敏感数据泄密，信息系统发布和传播系统发生篡改，影响系统部分客户的正常业务工作，或者被监管或主管单位通报，对单位造成较小损失或产生较小不良社会影响的。 | L23: 1、网络攻击类 1）外部攻击成功（webshell后门上传/远程命令执行/反序列化命令执行/远程漏洞利用成功/其他符合该等级的事件） 2）内部横向或内对外攻击成功（RDP暴力破解/系统命令执行/远程命令执行/其他符合该等级的事件） 2、病毒木马类 1）加密勒索软件/webshell后门/黑链/主机存在恶意命令执行/其他符合该等级的事件 | M23: 通告时间：从安全日志分析研判到通告，用时<30min 遏制影响时间：遏制影响时间<1h 准确率：安全事件经过人工确认后，准确率达到99% 闭环率：100% | N23: 抑制-->调查-->溯源-->处置-->加固
B24: 病毒木马 | C24: 感染型病毒（例：勒索病毒感染） | D24: 重大事件 | E24: 抑制：联动AF封堵外联目的IP/域名、联动EDR隔离主机可疑文件或主机网络权限 调查：联动EDR执行全盘查杀，关联主机流量侧行为日志调查扩散的影响范围 溯源：结合网络流量日志和主机操作日志，查明病毒文件上传途径 处置：清除主机病毒文件 加固：针对病毒文件上传途径做好安全加固（漏洞修复/加强密码策略/提高人员安全意识） | J24: 一般事件 （对标国家标准IV级事件） | K24: 因安全事件导致的内网小范围出现的网络延时或故障，信息系统功能缺陷或者短暂不可用，导致个别用户或者业务受影响等技术层面的事件，但是这些事件没有带来实际的损失和影响。 | L24: 1、网络攻击类 1）外部攻击成功（主机收到垃圾邮件/方法过滤/目录遍历攻击/过滤HTTP出错页面/其他符合该等级的事件） 2）内部横向或内对外攻击失败（漏洞利用攻击/SQL注入攻击/SMB暴力破解/其他符合该等级的事件） 2、病毒木马类 1）如僵尸网络/木马病毒/挖矿病毒/恶意文件/其他符合该等级的事件 | M24: 通告时间：从安全日志分析研判到通告，用时<30min 遏制影响时间：遏制影响时间<4h 准确率：安全事件经过人工确认后，准确率达到99% 闭环率：100% | N24: 抑制-->调查-->处置
C25: 非感染型病毒（例：主机访问黑客工具C2地址） | D25: 一般事件 | E25: 抑制：联动AF封堵外联目的IP/域名、联动EDR隔离主机可疑文件或主机网络权限 调查：联动EDR执行全盘查杀，关联主机流量侧行为日志调查扩散的影响范围 处置：清除主机病毒文件 | J25: 重大威胁 | K25: 攻击者对内网发起的有组织，有预谋的持续性网络攻击（如 APT） | L25: 1、网络攻击类 1）外部攻击失败（如APT攻击/持续性攻击） | M25: 通告时间：从安全日志分析研判到通告，用时<1h 遏制影响时间：遏制影响时间<1h 准确率：安全事件经过人工确认后，准确率达到99% 闭环率：100% | N25: 抑制-->处置
B26: 脆弱性利用 | C26: 漏洞（例：Shiro反序列化漏洞） | D26: 重大事件 | E26: 抑制：联动AF封堵攻击源IP 调查：查明主机是否存在对应利用的漏洞，核实是否存在被利用成功的痕迹 加固：加固漏洞补丁以及安全防护策略 | J26: 一般威胁 | K26: 攻击者对内网发起网络安全攻击，但是对业务未造成任何影响 | L26: 1、网络攻击类 1）外部攻击失败（如网站扫描/端口扫描/webshell上传/SQL注入攻击/其他符合该等级的事件） | M26: 通告时间：从安全日志分析研判到通告，用时<2h 遏制影响时限：遏制影响时间<4h 准确率：安全事件经过人工确认后，准确率达到99% 闭环率：100% | N26: 抑制
C27: 弱密码 | D27: 重大威胁 | E27: 调查：针对互联网用户和管理员账户弱密码登录成功的，实时通告预警，核实是否为用户正常登录,如为用户正常登录则提醒修改强密码，如非用户登录则提醒用户立即修改密码或禁用账户； 加固：立即修改单用户密码，在应用系统层面加强密码规则
B28: 业务连续性 | C28: 基础环境异常：安全组件日志无法同步或同步时延增大 | D28: 一般事件 | E28: 调查：查明组件是否运行正常，安全策略和日志是否有效 处置：针对安全设备存在的问题协调产品售后支持解决
C29: 业务访问中断：网站无法访问、设备接入云端平台离线 | D29: 重大事件 | E29: 调查：查明是否为网络中断或对应系统软件/硬件工作异常，及时通告预警； 处置：排除故障，恢复业务

Sheet 资产表
A1: 序号 | B1: *业务名称 | C1: *IP/URL | D1: *业务等级 | E1: *服务类型 | F1: *资产类型 | G1: 业务责任人 | H1: 业务责任人邮箱 | I1: 业务责任人电话 | J1: Agent ID | K1: 存活状态 | L1: 资产标签 | M1: 服务/端口 | N1: 操作系统 | O1: 数据库 | P1: 中间件 | Q1: 开发语言 | R1: 开发框架 | S1: 应用/服务 | T1: AF可防护 | U1: EDR状态 | V1: 设备产商 | W1: 设备名称 | X1: 域名/URL | Y1: 应用品牌 | Z1: 应用版本 | AA1: 资产管理部门 | AB1: 资产责任人 | AC1: 资产责任人邮箱 | AD1: 资产责任人电话 | AE1: 扫描设备 | AF1: 分支 | AG1: 安全域 | AH1: 公网IP | AI1: 映射端口 | AJ1: 被映射端口
A2: 1 | B2: 资产发现系统默认分组 | C2: 192.168.20.211 | D2: 一般 | E2: 服务外 | F2: 物联网设备 | K2: 在线 | M2: dhanalakshmi(34567) soap(8899) unknown(9530,34561) http(80) rtsp(554) | N2: linux | P2: uc-httpd 1.0.0 | R2: gSOAP 2.7 | W2: NETSurveillance(Xiongmai-Cameras-and-Surveillance)(uc-httpd),DVR | AG2: 内网
A3: 2 | B3: 资产发现系统默认分组 | C3: 192.168.17.248 | D3: 一般 | E3: 服务外 | F3: 服务器 | K3: 在线 | M3: http(9000,5357,8585) pando-pub(7680) mysql(3306) msrpc(49667,49665,49670,135,49675,49664,49666,49669,49668) netbios-ssn(139) ms-wbt-server(4490) microsoft-ds(445) unknown(55064,5040) | N3: windows | O3: MySQL | P3: HttpSvr Microsoft-HTTPAPI 2.0 Apple-HFS | W3: HttpSvr,Microsoft-HTTPAPI,Apple-HFS | AG3: 内网
A4: 3 | B4: 资产发现系统默认分组 | C4: 192.168.100.243 | D4: 一般 | E4: 服务外 | F4: 终端 | K4: 在线 | M4: ssh(22) tcpwrapped(64443) | N4: linux | AG4: 内网
A5: 4 | B5: 资产发现系统默认分组 | C5: 172.20.34.73 | D5: 一般 | E5: 服务外 | F5: 服务器 | K5: 在线 | M5: http(80) ssl(443,4480,23031,23020) ssh(22) iscsi(3260) | N5: linux | P5: Apache httpd | W5: Sangfor-Enterprise Cloud Platform(Apache httpd) | Y5: Sangfor Technologies Inc.(Apache Software Foundation) | AG5: 内网
A6: 5 | B6: 资产发现系统默认分组 | C6: 192.168.21.9 | D6: 一般 | E6: 服务外 | F6: 终端 | K6: 在线 | AG6: 内网
A7: 6 | B7: 资产发现系统默认分组 | C7: 192.168.21.4 | D7: 一般 | E7: 服务外 | F7: 终端 | K7: 在线 | AG7: 内网
A8: 7 | B8: 资产发现系统默认分组 | C8: 192.168.21.6 | D8: 一般 | E8: 服务外 | F8: 终端 | K8: 在线 | AG8: 内网
A9: 8 | B9: 资产发现系统默认分组 | C9: 192.168.21.230 | D9: 一般 | E9: 服务外 | F9: 终端 | K9: 在线 | AG9: 内网
A10: 9 | B10: 资产发现系统默认分组 | C10: 192.168.21.19 | D10: 一般 | E10: 服务外 | F10: 终端 | K10: 在线 | M10: unknown(17561) ms-wbt-server(3389) tcpwrapped(53000) afs3-callback(7001) soap(52000) wap-wsp(9200) | N10: windows | AG10: 内网
A11: 10 | B11: 资产发现系统默认分组 | C11: 192.168.22.238 | D11: 一般 | E11: 服务外 | F11: 物联网设备 | K11: 在线 | M11: http(80) ssl(443) rtsp(554) tcpwrapped(8686) upnp(5000) | N11: linux | T11: 是 | W11: dahua-camera | AA11: 天津 | AF11: 天津 | AG11: 内网
A12: 11 | B12: 资产发现系统默认分组 | C12: 192.168.17.158 | D12: 一般 | E12: 服务外 | F12: 终端 | K12: 在线 | AG12: 内网
A13: 12 | B13: 资产发现系统默认分组 | C13: 192.168.21.13 | D13: 一般 | E13: 服务外 | F13: 物联网设备 | K13: 在线 | M13: tcpwrapped(80) rtsp(554) dhanalakshmi(34567) unknown(9527,9530,34599) telnet(23) soap(8180) | N13: linux | W13: DVR | Y13: 无 | AG13: 内网
A14: 13 | B14: 资产发现系统默认分组 | C14: 192.168.23.220 | D14: 一般 | E14: 服务外 | F14: 物联网设备 | K14: 在线 | N14: linux | P14: eSoft Mongoose | W14: eSoft,Mongoose,mongo,DVR | AG14: 内网
A15: 14 | B15: 武汉极乐汤帝派鞋柜服务器 | C15: 192.168.4.219 | D15: 重要 | E15: 服务内(7*24H) | F15: 服务器 | K15: 在线 | L15: MSS-XDR | M15: ajp13(8009) http(8096) | N15: linux | P15: Apache Jserv | T15: 是 | AA15: 武汉 | AF15: 武汉 | AG15: 内网
A16: 15 | B16: 资产发现系统默认分组 | C16: 192.168.19.253 | D16: 一般 | E16: 服务外 | F16: 终端 | K16: 在线 | M16: targus-getdata(5200) upnp(5000) admd(5100) hacl-hb(5300) | N16: windows | AG16: 内网
A17: 16 | B17: 武汉漏扫工具TSS | C17: 192.168.4.214 | D17: 一般 | E17: 服务外 | F17: 扫描器 | K17: 在线 | M17: ssl(443) java-rmi(1099) http(8082) https(5680) | N17: linux | P17: OpenResty | R17: Bootstrap Table(jQuery) | T17: 是 | W17: OpenResty | Y17: OpenResty Inc. | AA17: 武汉 | AF17: 武汉 | AG17: 内网
A18: 17 | B18: 数据平台-数仓-主库 | C18: 172.16.6.50 | D18: 核心 | E18: 服务内(7*24H) | F18: 服务器 | J18: 1974090767 | K18: 在线 | L18: MSS-XDR | M18: ssh(22) rpcbind(111) oracle-tns(1521) oracle(31931) tcpwrapped(10050) raxa-mgmt(6099) | N18: linux | O18: Oracle | T18: 是 | U18: 在线 | AA18: 上海 | AF18: 上海 | AG18: 外网 | AH18: 122.144.156.35
A19: 18 | B19: 资产发现系统默认分组 | C19: 192.168.19.238 | D19: 一般 | E19: 服务外 | F19: 终端 | K19: 在线 | M19: telnet(23) jamlink(8091) tcpwrapped(554) http(80) | N19: linux | AG19: 内网
A20: 19 | B20: 资产发现系统默认分组 | C20: 192.168.88.67 | D20: 一般 | E20: 服务外 | F20: 物联网设备 | K20: 在线 | M20: onvif(3702) tor-socks(9050) soap(80) http-alt(8000) upnp(5000) login(513) http(8080) telnet(23) tcpwrapped(514,9001,554,21) cslistener(9000) | N20: linux | P20: WAPA-HttpServer | W20: WAPA-HttpServer | Y20: 无 | AG20: 内网
A21: 20 | B21: 资产发现系统默认分组 | C21: 192.168.24.223 | D21: 一般 | E21: 服务外 | F21: 物联网设备 | K21: 在线 | M21: rtsp(554) http(80) ssl(443) tcpwrapped(322) hikvision-nvr(8000) | N21: linux | P21: Webserver | W21: Hikvision-IP CAMERA,hikvision-camera,Hikvision-NVR(Webserver) | AG21: 内网
A22: 21 | B22: 资产发现系统默认分组 | C22: 192.168.88.64 | D22: 一般 | E22: 服务外 | F22: 物联网设备 | K22: 在线 | M22: onvif(3702) tor-socks(9050) soap(80) http-alt(8000) upnp(5000) login(513) http(8080) telnet(23) tcpwrapped(514,9001,554,21) cslistener(9000) | N22: linux | P22: WAPA-HttpServer | W22: WAPA-HttpServer | Y22: 无 | AG22: 内网
A23: 22 | B23: 资产发现系统默认分组 | C23: 192.168.24.19 | D23: 一般 | E23: 服务外 | F23: 物联网设备 | K23: 在线 | M23: http(80) unknown(37777) d-s-n(8086) rtsp(554) | R23: seajs(jQuery) | W23: dahua-camera | AG23: 内网
A24: 23 | B24: 资产发现系统默认分组 | C24: 192.168.19.26 | D24: 一般 | E24: 服务外 | F24: 终端 | K24: 在线 | M24: telnet(23) jamlink(8091) tcpwrapped(554) http(80) | N24: linux | AG24: 内网
A25: 24 | B25: 资产发现系统默认分组 | C25: 192.168.24.15 | D25: 一般 | E25: 服务外 | F25: 物联网设备 | K25: 在线 | M25: http(80) unknown(37777) d-s-n(8086) rtsp(554) | R25: seajs(jQuery) | W25: dahua-camera | AG25: 内网
A26: 25 | B26: 资产发现系统默认分组 | C26: 172.16.1.10 | D26: 一般 | E26: 服务外 | F26: 安全设备 | K26: 在线 | M26: ssl(443,4433,8443) | N26: linux | W26: Sangfor-aTrust | Y26: Sangfor Technologies Inc. | AG26: 内网
A27: 26 | B27: 资产发现系统默认分组 | C27: 192.168.24.218 | D27: 一般 | E27: 服务外 | F27: 物联网设备 | K27: 在线 | M27: http(80) unknown(37777) d-s-n(8086) rtsp(554) | R27: seajs(jQuery) | W27: dahua-camera | AG27: 内网
A28: 27 | B28: 资产发现系统默认分组 | C28: 192.168.24.188 | D28: 一般 | E28: 服务外 | F28: 物联网设备 | K28: 在线 | M28: http(80) unknown(37777) d-s-n(8086) rtsp(554) | R28: seajs(jQuery) | W28: dahua-camera | AG28: 内网
A29: 28 | B29: 资产发现系统默认分组 | C29: 192.168.24.130 | D29: 一般 | E29: 服务外 | F29: 物联网设备 | K29: 在线 | M29: http(80) unknown(37777) d-s-n(8086) rtsp(554) | R29: seajs(jQuery) | W29: dahua-camera | AG29: 内网
A30: 29 | B30: 资产发现系统默认分组 | C30: 192.168.24.207 | D30: 一般 | E30: 服务外 | F30: 物联网设备 | K30: 在线 | M30: http(80) unknown(37777) d-s-n(8086) rtsp(554) | R30: seajs(jQuery) | W30: dahua-camera | AG30: 内网
A31: 30 | B31: 资产发现系统默认分组 | C31: 192.168.19.162 | D31: 一般 | E31: 服务外 | F31: 物联网设备 | K31: 在线 | M31: http(80) hikvision-nvr(8000) rtsp(554) | N31: linux | P31: Webserver | W31: Hikvision-NVR(Webserver)(hikvision-camera),Hikvision-IP CAMERA | AG31: 内网
A32: 31 | B32: 资产发现系统默认分组 | C32: 172.16.1.21 | D32: 一般 | E32: 服务外 | F32: 网络设备 | K32: 在线 | M32: ssh(22) telnet(23) http(80) | N32: linux | P32: Apache httpd(Switch) | W32: Apache httpd(Switch)(Brocade-Switch) | AG32: 内网
A33: 32 | B33: 资产发现系统默认分组 | C33: 192.168.19.127 | D33: 一般 | E33: 服务外 | F33: 终端 | K33: 在线 | M33: telnet(23) jamlink(8091) tcpwrapped(554) http(80) | N33: linux | AG33: 内网
A34: 33 | B34: 资产发现系统默认分组 | C34: 192.168.19.213 | D34: 一般 | E34: 服务外 | F34: 终端 | K34: 在线 | M34: telnet(23) jamlink(8091) tcpwrapped(554) http(80) | N34: linux | AG34: 内网
A35: 34 | B35: 资产发现系统默认分组 | C35: 192.168.23.97 | D35: 一般 | E35: 服务外 | F35: 物联网设备 | K35: 在线 | M35: http(80) unknown(37777) d-s-n(8086) rtsp(554) | R35: seajs(jQuery) | W35: dahua-camera | AG35: 内网
A36: 35 | B36: 资产发现系统默认分组 | C36: 192.168.23.26 | D36: 一般 | E36: 服务外 | F36: 物联网设备 | K36: 在线 | M36: http(80) unknown(37777) d-s-n(8086) rtsp(554) | R36: seajs(jQuery) | W36: dahua-camera | AG36: 内网
A37: 36 | B37: 资产发现系统默认分组 | C37: 192.168.23.28 | D37: 一般 | E37: 服务外 | F37: 物联网设备 | K37: 在线 | M37: http(80) unknown(37777) d-s-n(8086) rtsp(554) | R37: seajs(jQuery) | W37: dahua-camera | AG37: 内网
A38: 37 | B38: 资产发现系统默认分组 | C38: 192.168.23.116 | D38: 一般 | E38: 服务外 | F38: 物联网设备 | K38: 在线 | M38: http(80) unknown(37777) d-s-n(8086) rtsp(554) | R38: seajs(jQuery) | W38: dahua-camera | AG38: 内网
A39: 38 | B39: 资产发现系统默认分组 | C39: 192.168.23.114 | D39: 一般 | E39: 服务外 | F39: 物联网设备 | K39: 在线 | M39: http(80) unknown(37777) d-s-n(8086) rtsp(554) | R39: seajs(jQuery) | W39: dahua-camera | AG39: 内网
A40: 39 | B40: 主数据库服务器（超融合机器） | C40: 192.168.9.100 | D40: 核心 | E40: 服务内(7*24H) | F40: 服务器 | J40: 836640792 | K40: 在线 | L40: MSS-XDR | M40: tcpwrapped(49456,31155,1521,10050,111,22) | T40: 是 | U40: 在线 | AA40: 成都 | AF40: 成都 | AG40: 内网
...

Sheet 暴露面
A1: 服务内容 | B1: 资产类型 | C1: 类型 | D1: 子类型 | E1: 总数 | F1: 影子资产数
A2: 互联网暴露面 | B2: 基础资产 | C2: 域名资产 | D2: 根域名资产 | E2: 1 | F2: 0
D3: 子域名资产 | E3: 7 | F3: 0
C4: IP资产 | D4: IP资产 | E4: 3 | F4: 2
C5: 端口资产 | D5: 端口资产 | E5: 27 | F5: 26
C6: WEB资产 | D6: WEB资产 | E6: 20 | F6: 19
C7: 非WEB资产 | D7: 非WEB资产 | E7: 7 | F7: 7
C8: 网络&安全设备 | D8: 网络&安全设备 | E8: 4 | F8: 4
C9: 云类资产 | D9: 云类资产 | E9: 0 | F9: 0
C10: SSL证书 | D10: SSL证书 | E10: 27 | F10: /
B11: 移动端资产 | C11: APP | D11: APP | E11: 0 | F11: /
C12: 公众号 | D12: 公众号 | E12: 0 | F12: /
C13: 小程序 | D13: 小程序 | E13: 0 | F13: /

Sheet 资产漏洞表
A1: 序号 | B1: 漏洞名称 | C1: 扫描方式 | D1: 漏洞类型 | E1: 漏洞等级 | F1: 是否可利用 | G1: 防护规则 | H1: 业务系统 | I1: 负责人 | J1: 受影响主机/位置 | K1: IP | L1: 端口 | M1: 版本号 | N1: 内/外网 | O1: 修复优先级 | P1: 跟进状态 | Q1: 备注信息 | R1: 来源 | S1: 发现时间 （填充此单元格为粉红色代表是最近扫描新增漏洞） | T1: 更新时间 | U1: 漏洞危害 | V1: 解决方案 | W1: 参考资料
A2: 1 | B2: SSH Diffie-Hellman 模数 <= 1024 位 (Logjam)(CVE-2015-4000) | C2: 版本比较 | D2: 系统漏洞 | E2: 低危 | F2: 否 | G2: 无效 | H2: 数据库服务器1（超融合机器） | I2: 未知责任人 | J2: 192.168.9.20 | K2: 192.168.9.20 | L2: 22 | M2: - | N2: =_xlfn.XLOOKUP(K2,资产表!C:C,资产表!AG:AG,“”) -> 内网 | O2: 建议修复 | P2: 处置中 | Q2: - | R2: TSS | S2: 45513.004 | T2: 46004.018 | U2: 这允许攻击者恢复明文或可能违反连接的完整性。 | V2: 重新配置服务以使用唯一的、2048 位或更高位数的 Diffie-Hellman moduli。 | W2: https://weakdh.org/ https://stribika.github.io/2015/01/04/secure-secure-shell.html https://www.cnnvd.org.cn/home/globalSearch?keyword=CNNVD-201505-428 http://www.securityfocus.com/bid/74733 http://www.securityfocus.com/bid/91787
A3: 2 | B3: SSH Diffie-Hellman 模数 <= 1024 位 (Logjam)(CVE-2015-4000) | C3: 版本比较 | D3: 系统漏洞 | E3: 低危 | F3: 否 | G3: 无效 | H3: zabbix代理服务器-成都 | I3: 未知责任人 | J3: 192.168.9.220 | K3: 192.168.9.220 | L3: 22 | M3: - | N3: =_xlfn.XLOOKUP(K3,资产表!C:C,资产表!AG:AG,“”) -> 内网 | O3: 建议修复 | P3: 处置中 | Q3: - | R3: TSS | S3: 45513.004 | T3: 46004.019 | U3: 这允许攻击者恢复明文或可能违反连接的完整性。 | V3: 重新配置服务以使用唯一的、2048 位或更高位数的 Diffie-Hellman moduli。 | W3: https://weakdh.org/ https://stribika.github.io/2015/01/04/secure-secure-shell.html https://www.cnnvd.org.cn/home/globalSearch?keyword=CNNVD-201505-428 http://www.securityfocus.com/bid/74733 http://www.securityfocus.com/bid/91787
A4: 3 | B4: 支持SSL 64位块大小的密码套件（SWEET32） | C4: 原理扫描 | D4: 系统漏洞 | E4: 高危 | F4: 否 | G4: 无效 | H4: 深大中间层-商餐服务器 | I4: 未知责任人 | J4: 172.20.34.80 | K4: 172.20.34.80 | L4: 3389 | M4: - | N4: =_xlfn.XLOOKUP(K4,资产表!C:C,资产表!AG:AG,“”) -> 外网 | O4: 尽快修复 | P4: 处置中 | Q4: - | R4: TSS | S4: 45513.005 | T4: 46004.019 | U4: 具有足够资源的中间人攻击者可利用此漏洞,通过“birthday”攻击检测会在固定密码与已知纯文本之间泄露 XOR 的冲突,进而泄露密码文本（例如安全 HTTPS Cookie）,并可能导致劫持经认证的会话。 | V4: 参见《支持SSL 64位块大小的密码套件（SWEET32）-修复方案》 | W4: https://blog.csdn.net/weixin_46167705/article/details/123374139
A5: 4 | B5: 支持SSL 64位块大小的密码套件（SWEET32） | C5: 原理扫描 | D5: 系统漏洞 | E5: 高危 | F5: 否 | G5: 无效 | H5: 深大中间层-闸机服务器 | I5: 未知责任人 | J5: 172.20.34.78 | K5: 172.20.34.78 | L5: 3389 | M5: - | N5: =_xlfn.XLOOKUP(K5,资产表!C:C,资产表!AG:AG,“”) -> 外网 | O5: 尽快修复 | P5: 处置中 | Q5: - | R5: TSS | S5: 45513.005 | T5: 46004.018 | U5: 具有足够资源的中间人攻击者可利用此漏洞,通过“birthday”攻击检测会在固定密码与已知纯文本之间泄露 XOR 的冲突,进而泄露密码文本（例如安全 HTTPS Cookie）,并可能导致劫持经认证的会话。 | V5: 参见《支持SSL 64位块大小的密码套件（SWEET32）-修复方案》 | W5: https://blog.csdn.net/weixin_46167705/article/details/123374139
A6: 5 | B6: 终端服务未使用网络级别身份验证（NLA） | C6: 原理扫描 | D6: 系统漏洞 | E6: 中危 | F6: 否 | G6: 无效 | H6: 深大中间层-商餐服务器 | I6: 未知责任人 | J6: 172.20.34.80 | K6: 172.20.34.80 | L6: 3389 | M6: - | N6: =_xlfn.XLOOKUP(K6,资产表!C:C,资产表!AG:AG,“”) -> 外网 | O6: 建议修复 | P6: 处置中 | Q6: - | R6: TSS | S6: 45513.005 | T6: 46004.019 | U6: 未使用该认证的远程主机受攻击的风险等级高。 | V6: 参见《终端服务未使用网络级别身份验证（NLA）-修复方案》 | W6: https://blog.csdn.net/spring_is_coming/article/details/124982320
A7: 6 | B7: 终端服务未使用网络级别身份验证（NLA） | C7: 原理扫描 | D7: 系统漏洞 | E7: 中危 | F7: 否 | G7: 无效 | H7: 深大中间层-票务服务器 | I7: 未知责任人 | J7: 172.20.34.70 | K7: 172.20.34.70 | L7: 3389 | M7: - | N7: =_xlfn.XLOOKUP(K7,资产表!C:C,资产表!AG:AG,“”) -> 外网 | O7: 建议修复 | P7: 处置中 | Q7: - | R7: TSS | S7: 45513.005 | T7: 46004.019 | U7: 未使用该认证的远程主机受攻击的风险等级高。 | V7: 参见《终端服务未使用网络级别身份验证（NLA）-修复方案》 | W7: https://blog.csdn.net/spring_is_coming/article/details/124982320
A8: 7 | B8: SSL RC4 加密套件支持检测 (Bar Mitzvah) | C8: 原理扫描 | D8: 系统漏洞 | E8: 中危 | F8: 否 | G8: 无效 | H8: 深大中间层-闸机服务器 | I8: 未知责任人 | J8: 172.20.34.78 | K8: 172.20.34.78 | L8: 3389 | M8: - | N8: =_xlfn.XLOOKUP(K8,资产表!C:C,资产表!AG:AG,“”) -> 外网 | O8: 建议修复 | P8: 处置中 | Q8: - | R8: TSS | S8: 45513.005 | T8: 46004.018 | U8: 攻击者可利用大量的密文推测明文，导致远程主机信息泄露。 | V8: 参见《SSL RC4 加密套件支持检测 (Bar Mitzvah)-修复方案》 | W8: https://www.imperva.com/docs/HII_Attacking_SSL_when_using_RC4.pdf https://blog.csdn.net/m0_54434140/article/details/126536929
A9: 8 | B9: 终端服务未使用网络级别身份验证（NLA） | C9: 原理扫描 | D9: 系统漏洞 | E9: 中危 | F9: 否 | G9: 无效 | H9: 深大中间层-闸机服务器 | I9: 未知责任人 | J9: 172.20.34.78 | K9: 172.20.34.78 | L9: 3389 | M9: - | N9: =_xlfn.XLOOKUP(K9,资产表!C:C,资产表!AG:AG,“”) -> 外网 | O9: 建议修复 | P9: 处置中 | Q9: - | R9: TSS | S9: 45513.006 | T9: 46004.018 | U9: 未使用该认证的远程主机受攻击的风险等级高。 | V9: 参见《终端服务未使用网络级别身份验证（NLA）-修复方案》 | W9: https://blog.csdn.net/spring_is_coming/article/details/124982320
A10: 9 | B10: SSH Diffie-Hellman 模数 <= 1024 位 (Logjam)(CVE-2015-4000) | C10: 版本比较 | D10: 系统漏洞 | E10: 低危 | F10: 否 | G10: 无效 | H10: 主数据库服务器（超融合机器） | I10: 未知责任人 | J10: 192.168.9.100 | K10: 192.168.9.100 | L10: 22 | M10: - | N10: =_xlfn.XLOOKUP(K10,资产表!C:C,资产表!AG:AG,“”) -> 内网 | O10: 建议修复 | P10: 处置中 | Q10: - | R10: TSS | S10: 45513.004 | T10: 46004.017 | U10: 这允许攻击者恢复明文或可能违反连接的完整性。 | V10: 重新配置服务以使用唯一的、2048 位或更高位数的 Diffie-Hellman moduli。 | W10: https://weakdh.org/ https://stribika.github.io/2015/01/04/secure-secure-shell.html https://www.cnnvd.org.cn/home/globalSearch?keyword=CNNVD-201505-428 http://www.securityfocus.com/bid/74733 http://www.securityfocus.com/bid/91787
A11: 10 | B11: Apache Tomcat 6.x < 6.0.35 多个漏洞 | C11: 版本比较 | D11: 系统漏洞 | E11: 中危 | F11: 否 | G11: 无效 | H11: 深大中间层-票务服务器 | I11: 未知责任人 | J11: 172.20.34.70 | K11: 172.20.34.70 | L11: 8030 | M11: - | N11: =_xlfn.XLOOKUP(K11,资产表!C:C,资产表!AG:AG,“”) -> 外网 | O11: 建议修复 | P11: 处置中 | Q11: - | R11: TSS | S11: 45513.005 | T11: 46004.019 | U11: 成功利用可能会导致敏感信息泄露或者拒绝服务的情况 | V11: 升级到 Apache Tomcat 6.0.35 或更高版本。 | W11: http://svn.apache.org/viewvc?view=revision&revision=1162959 https://bz.apache.org/bugzilla/show_bug.cgi?id=51698#c2 http://www.nruns.com/_downloads/advisory28122011.pdf http://tomcat.apache.org/security-6.html#Fixed_in_Apache_Tomcat_6.0.35 https://www.cnnvd.org.cn/home/globalSearch?keyword=CNNVD-201201-056,CNNVD-201201-195,CNNVD-201201-207,CNNVD-201108-510,CNNVD-201112-503 https://www.cnnvd.org.cn/home/globalSearch?keyword=CNNVD-201201-056,CNNVD-201201-195,CNNVD-201201-207,CNNVD-201108-510,CNNVD-201112-503 https://www.cnnvd.org.cn/home/globalSearch?keyword=CNNVD-201201-056,CNNVD-201201-195,CNNVD-201201-207,CNNVD-201108-510,CNNVD-201112-503 https://www.cnnvd.org.cn/home/globalSearch?keyword=CNNVD-201201-056,CNNVD-201201-195,CNNVD-201201-207,CNNVD-201108-510,CNNVD-201112-503 https://www.cnnvd.org.cn/home/globalSearch?keyword=CNNVD-201201-056,CNNVD-201201-195,CNNVD-201201-207,CNNVD-201108-510,CNNVD-201112-503
A12: 11 | B12: SSL RC4 加密套件支持检测 (Bar Mitzvah) | C12: 原理扫描 | D12: 系统漏洞 | E12: 中危 | F12: 否 | G12: 无效 | H12: 深大中间层-商餐服务器 | I12: 未知责任人 | J12: 172.20.34.80 | K12: 172.20.34.80 | L12: 3389 | M12: - | N12: =_xlfn.XLOOKUP(K12,资产表!C:C,资产表!AG:AG,“”) -> 外网 | O12: 建议修复 | P12: 处置中 | Q12: - | R12: TSS | S12: 45513.005 | T12: 46004.019 | U12: 攻击者可利用大量的密文推测明文，导致远程主机信息泄露。 | V12: 参见《SSL RC4 加密套件支持检测 (Bar Mitzvah)-修复方案》 | W12: https://www.imperva.com/docs/HII_Attacking_SSL_when_using_RC4.pdf https://blog.csdn.net/m0_54434140/article/details/126536929
A13: 12 | B13: Oracle Database Server Core RDBMS组件远程安全漏洞（CVE-2013-5858） | C13: 版本比较 | D13: 系统漏洞 | E13: 中危 | F13: 否 | G13: 无效 | H13: 数据库服务器1（超融合机器） | I13: 未知责任人 | J13: 192.168.9.20 | K13: 192.168.9.20 | L13: 1521 | M13: Oracle: 11.2.0.4 | N13: =_xlfn.XLOOKUP(K13,资产表!C:C,资产表!AG:AG,“”) -> 内网 | O13: 建议修复 | P13: 处置中 | Q13: - | R13: TSS | S13: 45513.007 | T13: 46004.018 | U13: 影响oracle:11.2.0.3版本,11.1.0.7版本,11.2.0.4版本,12.1.0.1版本 | V13: 厂商补丁：Oracle------Oracle已经为此发布了一个安全公告（cpujan2014-1972949）以及相应补丁:cpujan2014-1972949：Oracle Critical Patch Update Advisory - January 2014链接：http://www.oracle.com/technetwork/topics/security/cpujan2014-1972949.html
A14: 13 | B14: Oracle Database Server 'TNS Listener'远程数据投毒漏洞（CVE-2012-1675） | C14: 版本比较 | D14: 系统漏洞 | E14: 高危 | F14: 否 | G14: ips-11000221（有效） | H14: 数据库服务器1（超融合机器） | I14: 未知责任人 | J14: 192.168.9.20 | K14: 192.168.9.20 | L14: 1521 | M14: Oracle: 11.2.0.4 | N14: =_xlfn.XLOOKUP(K14,资产表!C:C,资产表!AG:AG,“”) -> 内网 | O14: 尽快修复 | P14: 处置中 | Q14: - | R14: TSS | S14: 45513.007 | T14: 46004.018 | U14: 影响oracle:10.2.0.3版本(含)到10.2.0.5版本(含),11.1.0.7版本,11.2.0.2版本,11.2.0.3版本,11.2.0.4版本 | V14: 厂商补丁： Oracle ------ Oracle已经为此发布了一个安全公告（alert-cve-2012-1675-1608180）以及相应补丁: alert-cve-2012-1675-1608180：Oracle Security Alert for CVE-2012-1675 链接：http://www.oracle.com/technetwork/topics/security/alert-cve-2012-1675-1608180.html | W14: http://www.oracle.com/technetwork/topics/security/alert-cve-2012-1675-1608180.html https://blogs.oracle.com/security/entry/security_alert_for_cve_2012 http://xforce.iss.net/xforce/xfdb/75303
A15: 14 | B15: Oracle Database Server Listener远程拒绝服务漏洞(CVE-2012-0072) | C15: 版本比较 | D15: 系统漏洞 | E15: 中危 | F15: 否 | G15: 无效 | H15: 数据库服务器1（超融合机器） | I15: 未知责任人 | J15: 192.168.9.20 | K15: 192.168.9.20 | L15: 1521 | M15: Oracle: 11.2.0.4 | N15: =_xlfn.XLOOKUP(K15,资产表!C:C,资产表!AG:AG,“”) -> 内网 | O15: 建议修复 | P15: 处置中 | Q15: - | R15: TSS | S15: 45513.007 | T15: 46004.018 | U15: 影响oracle:11.2.0.2版本(含)到11.2.0.5版本(含),10.2.0.5版本,11.1.0.7版本 | V15: Oracle已经为此发布了一个安全公告（cpujan2012-366304）以及相应补丁: cpujan2012-366304：Oracle Critical Patch Update Advisory - January 2012 链接：https://www.oracle.com/security-alerts/cpujan2012.html#AppendixDB | W15: https://www.oracle.com/security-alerts/cpujan2012.html https://www.cnvd.org.cn/flaw/show/CNVD-2012-0230
A16: 15 | B16: Oracle Database Server Core RDBMS远程拒绝服务漏洞 | C16: 版本比较 | D16: 系统漏洞 | E16: 中危 | F16: 否 | G16: 无效 | H16: 数据库服务器1（超融合机器） | I16: 未知责任人 | J16: 192.168.9.20 | K16: 192.168.9.20 | L16: 1521 | M16: Oracle: 11.2.0.4 | N16: =_xlfn.XLOOKUP(K16,资产表!C:C,资产表!AG:AG,“”) -> 内网 | O16: 建议修复 | P16: 处置中 | Q16: - | R16: TSS | S16: 45513.007 | T16: 46004.018 | U16: 影响oracle:11.2.0.2版本(含)到11.2.0.5版本(含),10.2.0.5版本,11.1.0.7版本 | V16: Oracle已经为此发布了一个安全公告（cpujan2012-366304）以及相应补丁: cpujan2012-366304：Oracle Critical Patch Update Advisory - January 2012 链接：http://www.oracle.com/technetwork/topics/security/cpujan2012-366304.html | W16: https://www.oracle.com/security-alerts/cpujan2012.html https://cve.mitre.org/cgi-bin/cvename.cgi?name=CVE-2012-0082 http://www.oracle.com/technetwork/topics/security/cpujan2012-366304.html#AppendixDB https://www.cnvd.org.cn/flaw/show/CNVD-2012-0231
A17: 16 | B17: Oracle Database Server Spatial组件本地安全漏洞（CVE-2014-0378） | C17: 版本比较 | D17: 系统漏洞 | E17: 中危 | F17: 否 | G17: 无效 | H17: 数据库服务器1（超融合机器） | I17: 未知责任人 | J17: 192.168.9.20 | K17: 192.168.9.20 | L17: 1521 | M17: Oracle: 11.2.0.4 | N17: =_xlfn.XLOOKUP(K17,资产表!C:C,资产表!AG:AG,“”) -> 内网 | O17: 建议修复 | P17: 处置中 | Q17: - | R17: TSS | S17: 45513.007 | T17: 46004.018 | U17: 影响oracle:11.2.0.3版本,11.1.0.7版本,11.2.0.4版本,12.1.0.1版本 | V17: 厂商补丁：Oracle------Oracle已经为此发布了一个安全公告（cpujan2014-1972949）以及相应补丁:cpujan2014-1972949：Oracle Critical Patch Update Advisory - January 2014链接：http://www.oracle.com/technetwork/topics/security/cpujan2014-1972949.html
A18: 17 | B18: Oracle Database Server远程安全漏洞(CVE-2014-4236) | C18: 版本比较 | D18: 系统漏洞 | E18: 中危 | F18: 否 | G18: 无效 | H18: 数据库服务器1（超融合机器） | I18: 未知责任人 | J18: 192.168.9.20 | K18: 192.168.9.20 | L18: 1521 | M18: Oracle: 11.2.0.4 | N18: =_xlfn.XLOOKUP(K18,资产表!C:C,资产表!AG:AG,“”) -> 内网 | O18: 建议修复 | P18: 处置中 | Q18: - | R18: TSS | S18: 45513.007 | T18: 46004.018 | U18: 影响oracle:12.1.0.1版本,11.2.0.4版本 | V18: 厂商补丁：Oracle------Oracle已经为此发布了一个安全公告（cpujul2014-1972956）以及相应补丁:cpujul2014-1972956：Oracle Critical Patch Update Advisory - July 2014链接：http://www.oracle.com/technetwork/topics/security/cpujul2014-1972956.html
A19: 18 | B19: Oracle Database Server Jpublisher组件安全漏洞(CVE-2014-4293) | C19: 版本比较 | D19: 系统漏洞 | E19: 中危 | F19: 否 | G19: 无效 | H19: 数据库服务器1（超融合机器） | I19: 未知责任人 | J19: 192.168.9.20 | K19: 192.168.9.20 | L19: 1521 | M19: Oracle: 11.2.0.4 | N19: =_xlfn.XLOOKUP(K19,资产表!C:C,资产表!AG:AG,“”) -> 内网 | O19: 建议修复 | P19: 处置中 | Q19: - | R19: TSS | S19: 45513.007 | T19: 46004.018 | U19: 影响oracle:11.1.0.7版本,11.2.0.3版本,11.2.0.4版本,12.1.0.1版本,12.1.0.2版本 | V19: 目前厂商已经发布了升级补丁以修复此安全问题，补丁获取链接：http://www.oracle.com/technetwork/topics/security/cpuoct2014-1972960.html | W19: http://www.oracle.com/technetwork/topics/security/cpuoct2014-1972960.html https://cve.mitre.org/cgi-bin/cvename.cgi?name=CVE-2014-4293 https://www.cnvd.org.cn/flaw/show/CNVD-2014-07109
A20: 19 | B20: Oracle Database Server Java VM组件安全漏洞(CVE-2014-4294) | C20: 版本比较 | D20: 系统漏洞 | E20: 中危 | F20: 否 | G20: 无效 | H20: 数据库服务器1（超融合机器） | I20: 未知责任人 | J20: 192.168.9.20 | K20: 192.168.9.20 | L20: 1521 | M20: Oracle: 11.2.0.4 | N20: =_xlfn.XLOOKUP(K20,资产表!C:C,资产表!AG:AG,“”) -> 内网 | O20: 建议修复 | P20: 处置中 | Q20: - | R20: TSS | S20: 45513.007 | T20: 46004.018 | U20: 影响oracle:11.1.0.7版本,11.2.0.3版本,11.2.0.4版本,12.1.0.1版本,12.1.0.2版本 | V20: 目前厂商已经发布了升级补丁以修复此安全问题，补丁获取链接：http://www.oracle.com/technetwork/topics/security/cpuoct2014-1972960.html | W20: http://www.oracle.com/technetwork/topics/security/cpuoct2014-1972960.html https://cve.mitre.org/cgi-bin/cvename.cgi?name=CVE-2014-4294 https://www.cnvd.org.cn/flaw/show/CNVD-2014-07113
A21: 20 | B21: Oracle Database Server Jpublisher组件安全漏洞(CVE-2014-4297) | C21: 版本比较 | D21: 系统漏洞 | E21: 中危 | F21: 否 | G21: 无效 | H21: 数据库服务器1（超融合机器） | I21: 未知责任人 | J21: 192.168.9.20 | K21: 192.168.9.20 | L21: 1521 | M21: Oracle: 11.2.0.4 | N21: =_xlfn.XLOOKUP(K21,资产表!C:C,资产表!AG:AG,“”) -> 内网 | O21: 建议修复 | P21: 处置中 | Q21: - | R21: TSS | S21: 45513.007 | T21: 46004.018 | U21: 影响oracle:11.1.0.7版本,11.2.0.3版本,11.2.0.4版本,12.1.0.1版本,12.1.0.2版本 | V21: 目前厂商已经发布了升级补丁以修复此安全问题，补丁获取链接：http://www.oracle.com/technetwork/topics/security/cpuoct2014-1972960.html | W21: http://www.oracle.com/technetwork/topics/security/cpuoct2014-1972960.html https://cve.mitre.org/cgi-bin/cvename.cgi?name=CVE-2014-4297 https://www.cnvd.org.cn/flaw/show/CNVD-2014-07269
A22: 21 | B22: Oracle Database Server SQLJ组件安全漏洞(CVE-2014-4298) | C22: 版本比较 | D22: 系统漏洞 | E22: 中危 | F22: 否 | G22: 无效 | H22: 数据库服务器1（超融合机器） | I22: 未知责任人 | J22: 192.168.9.20 | K22: 192.168.9.20 | L22: 1521 | M22: Oracle: 11.2.0.4 | N22: =_xlfn.XLOOKUP(K22,资产表!C:C,资产表!AG:AG,“”) -> 内网 | O22: 建议修复 | P22: 处置中 | Q22: - | R22: TSS | S22: 45513.007 | T22: 46004.018 | U22: 影响oracle:11.1.0.7版本,11.2.0.3版本,11.2.0.4版本,12.1.0.1版本,12.1.0.2版本 | V22: 目前厂商已经发布了升级补丁以修复此安全问题，补丁获取链接：http://www.oracle.com/technetwork/topics/security/cpuoct2014-1972960.html | W22: http://www.oracle.com/technetwork/topics/security/cpuoct2014-1972960.html https://cve.mitre.org/cgi-bin/cvename.cgi?name=CVE-2014-4298 https://www.cnvd.org.cn/flaw/show/CNVD-2014-07122
A23: 22 | B23: Oracle Database Server SQLJ组件安全漏洞(CVE-2014-4300) | C23: 版本比较 | D23: 系统漏洞 | E23: 中危 | F23: 否 | G23: 无效 | H23: 数据库服务器1（超融合机器） | I23: 未知责任人 | J23: 192.168.9.20 | K23: 192.168.9.20 | L23: 1521 | M23: Oracle: 11.2.0.4 | N23: =_xlfn.XLOOKUP(K23,资产表!C:C,资产表!AG:AG,“”) -> 内网 | O23: 建议修复 | P23: 处置中 | Q23: - | R23: TSS | S23: 45513.007 | T23: 46004.018 | U23: 影响oracle:11.1.0.7版本,11.2.0.3版本,11.2.0.4版本,12.1.0.1版本,12.1.0.2版本 | V23: 目前厂商已经发布了升级补丁以修复此安全问题，补丁获取链接：http://www.oracle.com/technetwork/topics/security/cpuoct2014-1972960.html | W23: http://www.oracle.com/technetwork/topics/security/cpuoct2014-1972960.html https://cve.mitre.org/cgi-bin/cvename.cgi?name=CVE-2014-4300 https://www.cnvd.org.cn/flaw/show/CNVD-2014-07124
A24: 23 | B24: Oracle Database Server Java VM组件代码执行漏洞(CVE-2014-6453) | C24: 版本比较 | D24: 系统漏洞 | E24: 高危 | F24: 否 | G24: 无效 | H24: 数据库服务器1（超融合机器） | I24: 未知责任人 | J24: 192.168.9.20 | K24: 192.168.9.20 | L24: 1521 | M24: Oracle: 11.2.0.4 | N24: =_xlfn.XLOOKUP(K24,资产表!C:C,资产表!AG:AG,“”) -> 内网 | O24: 尽快修复 | P24: 处置中 | Q24: - | R24: TSS | S24: 45513.007 | T24: 46004.018 | U24: 影响oracle:11.1.0.7版本,11.2.0.3版本,11.2.0.4版本,12.1.0.1版本,12.1.0.2版本 | V24: 厂商补丁：目前厂商已经发布升级补丁解决此安全问题，补丁获取链接：http://www.oracle.com/technetwork/topics/security/cpuoct2014-1972960.html | W24: https://www.oracle.com/security-alerts/cpuoct2014verbose.html http://www.oracle.com/technetwork/topics/security/cpuoct2014-1972960.html
A25: 24 | B25: Oracle Database Server Java VM组件代码执行漏洞(CVE-2014-6467) | C25: 版本比较 | D25: 系统漏洞 | E25: 高危 | F25: 否 | G25: 无效 | H25: 数据库服务器1（超融合机器） | I25: 未知责任人 | J25: 192.168.9.20 | K25: 192.168.9.20 | L25: 1521 | M25: Oracle: 11.2.0.4 | N25: =_xlfn.XLOOKUP(K25,资产表!C:C,资产表!AG:AG,“”) -> 内网 | O25: 尽快修复 | P25: 处置中 | Q25: - | R25: TSS | S25: 45513.007 | T25: 46004.018 | U25: 影响oracle:11.1.0.7版本,11.2.0.3版本,11.2.0.4版本,12.1.0.1版本,12.1.0.2版本 | V25: 厂商补丁：目前Oracle厂商已经发布升级补丁解决此安全问题，补丁获取链接：http://www.oracle.com/technetwork/topics/security/cpuoct2014-1972960.html | W25: https://www.oracle.com/security-alerts/cpuoct2014verbose.html https://cve.mitre.org/cgi-bin/cvename.cgi?name=CVE-2014-6467 https://www.cnvd.org.cn/flaw/show/CNVD-2014-07116 http://www.oracle.com/technetwork/topics/security/cpuoct2014-1972960.html
A26: 25 | B26: Oracle Database Server Jpublisher组件漏洞(CVE-2014-6477) | C26: 版本比较 | D26: 系统漏洞 | E26: 中危 | F26: 否 | G26: 无效 | H26: 数据库服务器1（超融合机器） | I26: 未知责任人 | J26: 192.168.9.20 | K26: 192.168.9.20 | L26: 1521 | M26: Oracle: 11.2.0.4 | N26: =_xlfn.XLOOKUP(K26,资产表!C:C,资产表!AG:AG,“”) -> 内网 | O26: 建议修复 | P26: 处置中 | Q26: - | R26: TSS | S26: 45513.007 | T26: 46004.018 | U26: 影响oracle:11.1.0.7版本,11.2.0.3版本,11.2.0.4版本,12.1.0.1版本,12.1.0.2版本 | V26: 厂商补丁Oracle------目前厂商已经发布了升级补丁以修复此安全问题，如有具体升级详情问题可咨询oracle厂商，补丁获取链接： http://www.oracle.com/technetwork/topics/security/cpuoct2014-1972960.html | W26: https://www.oracle.com/security-alerts/cpuoct2014verbose.html https://cve.mitre.org/cgi-bin/cvename.cgi?name=CVE-2014-6477 https://www.cnvd.org.cn/flaw/show/CNVD-2014-08588
A27: 26 | B27: Oracle Database Server Java VM组件安全漏洞(CVE-2014-6538) | C27: 版本比较 | D27: 系统漏洞 | E27: 中危 | F27: 否 | G27: 无效 | H27: 数据库服务器1（超融合机器） | I27: 未知责任人 | J27: 192.168.9.20 | K27: 192.168.9.20 | L27: 1521 | M27: Oracle: 11.2.0.4 | N27: =_xlfn.XLOOKUP(K27,资产表!C:C,资产表!AG:AG,“”) -> 内网 | O27: 建议修复 | P27: 处置中 | Q27: - | R27: TSS | S27: 45513.007 | T27: 46004.018 | U27: 影响oracle:11.1.0.7版本,11.2.0.3版本,11.2.0.4版本,12.1.0.1版本,12.1.0.2版本 | V27: 目前厂商已经发布了升级补丁以修复此安全问题，补丁获取链接：http://www.oracle.com/technetwork/topics/security/cpuoct2014-1972960.html | W27: http://www.oracle.com/technetwork/topics/security/cpuoct2014-1972960.html https://cve.mitre.org/cgi-bin/cvename.cgi?name=CVE-2014-6538 https://www.cnvd.org.cn/flaw/show/CNVD-2014-07260
A28: 27 | B28: Oracle Database Server SQLJ组件安全漏洞(CVE-2014-6542) | C28: 版本比较 | D28: 系统漏洞 | E28: 中危 | F28: 否 | G28: 无效 | H28: 数据库服务器1（超融合机器） | I28: 未知责任人 | J28: 192.168.9.20 | K28: 192.168.9.20 | L28: 1521 | M28: Oracle: 11.2.0.4 | N28: =_xlfn.XLOOKUP(K28,资产表!C:C,资产表!AG:AG,“”) -> 内网 | O28: 建议修复 | P28: 处置中 | Q28: - | R28: TSS | S28: 45513.007 | T28: 46004.018 | U28: 影响oracle:11.1.0.7版本,11.2.0.3版本,11.2.0.4版本,12.1.0.1版本,12.1.0.2版本 | V28: 目前厂商已经发布了升级补丁以修复此安全问题，补丁获取链接：http://www.oracle.com/technetwork/topics/security/cpuoct2014-1972960.html | W28: http://www.oracle.com/technetwork/topics/security/cpuoct2014-1972960.html https://cve.mitre.org/cgi-bin/cvename.cgi?name=CVE-2014-6542 https://www.cnvd.org.cn/flaw/show/CNVD-2014-07117
A29: 28 | B29: Oracle Database Server Jpublisher组件安全漏洞(CVE-2014-6547) | C29: 版本比较 | D29: 系统漏洞 | E29: 中危 | F29: 否 | G29: 无效 | H29: 数据库服务器1（超融合机器） | I29: 未知责任人 | J29: 192.168.9.20 | K29: 192.168.9.20 | L29: 1521 | M29: Oracle: 11.2.0.4 | N29: =_xlfn.XLOOKUP(K29,资产表!C:C,资产表!AG:AG,“”) -> 内网 | O29: 建议修复 | P29: 处置中 | Q29: - | R29: TSS | S29: 45513.007 | T29: 46004.018 | U29: 影响oracle:11.1.0.7版本,11.2.0.3版本,11.2.0.4版本,12.1.0.1版本,12.1.0.2版本 | V29: 目前厂商已经发布了升级补丁以修复此安全问题，补丁获取链接：http://www.oracle.com/technetwork/topics/security/cpuoct2014-1972960.html | W29: http://www.oracle.com/technetwork/topics/security/cpuoct2014-1972960.html https://cve.mitre.org/cgi-bin/cvename.cgi?name=CVE-2014-6547 https://www.cnvd.org.cn/flaw/show/CNVD-2014-07128
A30: 29 | B30: Oracle Database Server远程安全漏洞(CVE-2015-0371) | C30: 版本比较 | D30: 系统漏洞 | E30: 中危 | F30: 否 | G30: 无效 | H30: 数据库服务器1（超融合机器） | I30: 未知责任人 | J30: 192.168.9.20 | K30: 192.168.9.20 | L30: 1521 | M30: Oracle: 11.2.0.4 | N30: =_xlfn.XLOOKUP(K30,资产表!C:C,资产表!AG:AG,“”) -> 内网 | O30: 建议修复 | P30: 处置中 | Q30: - | R30: TSS | S30: 45513.007 | T30: 46004.018 | U30: 影响oracle:11.2.0.3版本,11.1.0.7版本,11.2.0.4版本,12.1.0.1版本 | V30: Oracle------Oracle已经为此发布了一个安全公告（cpujan2015-1972971）以及相应补丁:cpujan2015-1972971：Oracle Critical Patch Update Advisory - January 2015链接：http://www.oracle.com/technetwork/topics/security/cpujan2015-1972971.html
A31: 30 | B31: Oracle Database Server OJVM组件安全漏洞(CVE-2015-0373) | C31: 版本比较 | D31: 系统漏洞 | E31: 中危 | F31: 否 | G31: 无效 | H31: 数据库服务器1（超融合机器） | I31: 未知责任人 | J31: 192.168.9.20 | K31: 192.168.9.20 | L31: 1521 | M31: Oracle: 11.2.0.4 | N31: =_xlfn.XLOOKUP(K31,资产表!C:C,资产表!AG:AG,“”) -> 内网 | O31: 建议修复 | P31: 处置中 | Q31: - | R31: TSS | S31: 45513.007 | T31: 46004.018 | U31: 影响oracle:11.2.0.4版本,11.2.0.3版本,12.1.0.2版本,12.1.0.1版本,11.1.0.7版本 | V31: 目前厂商已经发布了升级补丁以修复此安全问题，补丁获取链接：http://www.oracle.com/technetwork/topics/security/cpujan2015-1972971.html | W31: http://www.oracle.com/technetwork/topics/security/cpujan2015-1972971.html https://cve.mitre.org/cgi-bin/cvename.cgi?name=CVE-2015-0373 https://www.cnvd.org.cn/flaw/show/CNVD-2015-00530
A32: 31 | B32: Oracle Database Server XDB - XML Database组件安全漏洞(CVE-2015-0455) | C32: 版本比较 | D32: 系统漏洞 | E32: 中危 | F32: 否 | G32: 无效 | H32: 数据库服务器1（超融合机器） | I32: 未知责任人 | J32: 192.168.9.20 | K32: 192.168.9.20 | L32: 1521 | M32: Oracle: 11.2.0.4 | N32: =_xlfn.XLOOKUP(K32,资产表!C:C,资产表!AG:AG,“”) -> 内网 | O32: 建议修复 | P32: 处置中 | Q32: - | R32: TSS | S32: 45513.007 | T32: 46004.018 | U32: 影响oracle:11.2.0.3版本,11.2.0.4版本,12.1.0.2版本,12.1.0.1版本 | V32: 厂商补丁：Oracle已经为此发布了一个安全公告（cpuapr2015-2365600）以及相应补丁: cpuapr2015-2365600：Oracle Critical Patch Update Advisory - April 2015 链接：http://www.oracle.com/technetwork/topics/security/cpuapr2015-2365600.html | W32: http://www.oracle.com/technetwork/topics/security/cpuapr2015-2365600.html https://cve.mitre.org/cgi-bin/cvename.cgi?name=CVE-2015-0455 https://www.cnvd.org.cn/flaw/show/CNVD-2015-02520
A33: 32 | B33: Oracle Database 远程安全漏洞(CVE-2015-2599) | C33: 版本比较 | D33: 系统漏洞 | E33: 中危 | F33: 否 | G33: 无效 | H33: 数据库服务器1（超融合机器） | I33: 未知责任人 | J33: 192.168.9.20 | K33: 192.168.9.20 | L33: 1521 | M33: Oracle: 11.2.0.4 | N33: =_xlfn.XLOOKUP(K33,资产表!C:C,资产表!AG:AG,“”) -> 内网 | O33: 建议修复 | P33: 处置中 | Q33: - | R33: TSS | S33: 45513.007 | T33: 46004.018 | U33: 影响oracle:11.2.0.4版本,11.2.0.3版本,12.1.0.2版本,12.1.0.1版本,11.1.0.7版本 | V33: 厂商补丁:Oracle------Oracle已经为此发布了一个安全公告（cpujul2015-2367936）以及相应补丁:cpujul2015-2367936：Oracle Critical Patch Update Advisory - July 2015链接：http://www.oracle.com/technetwork/topics/security/cpujul2015-2367936.html
A34: 33 | B34: Oracle Database Server Java VM组件任意代码执行漏洞(CVE-2015-2629) | C34: 版本比较 | D34: 系统漏洞 | E34: 高危 | F34: 否 | G34: 无效 | H34: 数据库服务器1（超融合机器） | I34: 未知责任人 | J34: 192.168.9.20 | K34: 192.168.9.20 | L34: 1521 | M34: Oracle: 11.2.0.4 | N34: =_xlfn.XLOOKUP(K34,资产表!C:C,资产表!AG:AG,“”) -> 内网 | O34: 尽快修复 | P34: 处置中 | Q34: - | R34: TSS | S34: 45513.007 | T34: 46004.018 | U34: 影响oracle:11.2.0.4版本,11.2.0.3版本,12.1.0.2版本,12.1.0.1版本,11.1.0.7版本 | V34: Oracle已经为此发布了一个安全公告（cpujul2015-2367936）以及相应补丁: cpujul2015-2367936：Oracle Critical Patch Update Advisory - July 2015 链接：http://www.oracle.com/technetwork/topics/security/cpujul2015-2367936.html | W34: http://www.oracle.com/technetwork/topics/security/cpujul2015-2367936.html
A35: 34 | B35: Oracle Enterprise Manager Grid Control Enterprise Manager for Oracle Database组件安全漏洞(CVE-2015-2646) | C35: 版本比较 | D35: 系统漏洞 | E35: 中危 | F35: 否 | G35: 无效 | H35: 数据库服务器1（超融合机器） | I35: 未知责任人 | J35: 192.168.9.20 | K35: 192.168.9.20 | L35: 1521 | M35: Oracle: 11.2.0.4 | N35: =_xlfn.XLOOKUP(K35,资产表!C:C,资产表!AG:AG,“”) -> 内网 | O35: 建议修复 | P35: 处置中 | Q35: - | R35: TSS | S35: 45513.007 | T35: 46004.018 | U35: 影响oracle:11.2.0.3版本,11.2.0.4版本,11.1.0.7版本 | V35: 厂商补丁：Oracle------目前厂商已经发布了升级补丁以修复此安全问题，补丁获取链接：http://www.oracle.com/technetwork/topics/security/cpujul2015-2367936.html | W35: http://www.oracle.com/technetwork/topics/security/cpujul2015-2367936.html
A36: 35 | B36: Oracle Database Server Java VM组件安全漏洞(CVE-2015-4794) | C36: 版本比较 | D36: 系统漏洞 | E36: 高危 | F36: 否 | G36: 无效 | H36: 数据库服务器1（超融合机器） | I36: 未知责任人 | J36: 192.168.9.20 | K36: 192.168.9.20 | L36: 1521 | M36: Oracle: 11.2.0.4 | N36: =_xlfn.XLOOKUP(K36,资产表!C:C,资产表!AG:AG,“”) -> 内网 | O36: 尽快修复 | P36: 处置中 | Q36: - | R36: TSS | S36: 45513.007 | T36: 46004.018 | U36: 影响oracle:11.2.0.4版本,12.1.0.2版本,12.1.0.1版本 | V36: Oracle------Oracle已经为此发布了一个安全公告（cpuoct2015-2367953）以及相应补丁:cpuoct2015-2367953：Oracle Critical Patch Update Advisory - October 2015链接：http://www.oracle.com/technetwork/topics/security/cpuoct2015-2367953.html补丁下载：https://support.oracle.com/rs?type=doc&id=2049800.1 | W36: https://www.oracle.com/security-alerts/cpuoct2015verbose.html https://cve.mitre.org/cgi-bin/cvename.cgi?name=CVE-2015-4794 https://www.cnvd.org.cn/flaw/show/CNVD-2015-06948
A37: 36 | B37: Oracle Database Server Core RDBMS组件远程信息泄露安全漏洞（CVE-2014-0377） | C37: 版本比较 | D37: 系统漏洞 | E37: 中危 | F37: 否 | G37: 无效 | H37: 数据库服务器1（超融合机器） | I37: 未知责任人 | J37: 192.168.9.20 | K37: 192.168.9.20 | L37: 1521 | M37: Oracle: 11.2.0.4 | N37: =_xlfn.XLOOKUP(K37,资产表!C:C,资产表!AG:AG,“”) -> 内网 | O37: 建议修复 | P37: 处置中 | Q37: - | R37: TSS | S37: 45513.007 | T37: 46004.018 | U37: 影响oracle:11.2.0.3版本,11.1.0.7版本,11.2.0.4版本,12.1.0.1版本 | V37: 厂商补丁：Oracle------Oracle已经为此发布了一个安全公告（cpujan2014-1972949）以及相应补丁:cpujan2014-1972949：Oracle Critical Patch Update Advisory - January 2014链接：http://www.oracle.com/technetwork/topics/security/cpujan2014-1972949.html
A38: 37 | B38: Oracle Database 远程安全漏洞(CVE-2014-2406) | C38: 版本比较 | D38: 系统漏洞 | E38: 高危 | F38: 否 | G38: 无效 | H38: 数据库服务器1（超融合机器） | I38: 未知责任人 | J38: 192.168.9.20 | K38: 192.168.9.20 | L38: 1521 | M38: Oracle: 11.2.0.4 | N38: =_xlfn.XLOOKUP(K38,资产表!C:C,资产表!AG:AG,“”) -> 内网 | O38: 尽快修复 | P38: 处置中 | Q38: - | R38: TSS | S38: 45513.007 | T38: 46004.018 | U38: 影响oracle:11.2.0.3版本,11.2.0.4版本,11.1.0.7版本,11.1.0.1版本 | V38: 厂商补丁：Oracle------Oracle已经为此发布了一个安全公告（cpuapr2014-1972952）以及相应补丁:cpuapr2014-1972952：Oracle Critical Patch Update Advisory - April 2014链接：http://www.oracle.com/technetwork/topics/security/cpuapr2014-1972952.html https://support.oracle.com/rs?type=doc&id=1618213.1
A39: 38 | B39: Oracle Database Server DBMS_LDAP 远程安全漏洞(CVE-2014-3566) | C39: 版本比较 | D39: 系统漏洞 | E39: 低危 | F39: 否 | G39: 无效 | H39: 数据库服务器1（超融合机器） | I39: 未知责任人 | J39: 192.168.9.20 | K39: 192.168.9.20 | L39: 1521 | M39: Oracle: 11.2.0.4 | N39: =_xlfn.XLOOKUP(K39,资产表!C:C,资产表!AG:AG,“”) -> 内网 | O39: 建议修复 | P39: 处置中 | Q39: - | R39: TSS | S39: 45513.007 | T39: 46004.018 | U39: 影响oracle:11.2.0.4版本,12.1.0.2版本 | V39: 厂商补丁：Oracle------Oracle已经为此发布了一个安全公告（cpujul2017-3236622）以及相应补丁:cpujul2017-3236622：Oracle Critical Patch Update Advisory - July 2017链接：http://www.oracle.com/technetwork/security-advisory/cpujul2017-3236622.html
A40: 39 | B40: Oracle Database Server远程安全漏洞(CVE-2014-4237) | C40: 版本比较 | D40: 系统漏洞 | E40: 中危 | F40: 否 | G40: 无效 | H40: 数据库服务器1（超融合机器） | I40: 未知责任人 | J40: 192.168.9.20 | K40: 192.168.9.20 | L40: 1521 | M40: Oracle: 11.2.0.4 | N40: =_xlfn.XLOOKUP(K40,资产表!C:C,资产表!AG:AG,“”) -> 内网 | O40: 建议修复 | P40: 处置中 | Q40: - | R40: TSS | S40: 45513.007 | T40: 46004.018 | U40: 影响oracle:12.1.0.1版本,11.2.0.4版本 | V40: 厂商补丁：Oracle------Oracle已经为此发布了一个安全公告（cpujul2014-1972956）以及相应补丁:cpujul2014-1972956：Oracle Critical Patch Update Advisory - July 2014链接：http://www.oracle.com/technetwork/topics/security/cpujul2014-1972956.html
...

Sheet 弱密码

Sheet 告警表
A1: 告警名称 | B1: 告警优先级 | C1: 主机IP | D1: 威胁类型 | E1: 告警状态 | F1: 告警ID | G1: 服务组 | H1: 主机名称 | I1: 设备 | J1: IOC | K1: 告警标签 | L1: 首次触发时间 | M1: 最近触发时间 | N1: 处理人 | O1: 事件ID | P1: 威胁等级 | Q1: 失陷情况 | R1: 源IP | S1: 目的IP | T1: XFF IP | U1: USECASE ID | V1: 服务类型 | W1: 资产类别 | X1: 资产信息 | Y1: 服务经理 | Z1: 创建时间 | AA1: 实际处理人 | AB1: 同步状态 | AC1: 场景标签 | AD1: 攻击结果 | AE1: 访问方向 | AF1: 确定性等级 | AG1: 审核时长 | AH1: 操作时间 | AI1: 任务名称 | AJ1: sip联动状态 | AK1: 源端口 | AL1: 目的端口 | AM1: 协议 | AN1: 审核id | AO1: 拦截情况 | AP1: Sla | AQ1: 审核到期时间 | AR1: 可信度 | AS1: 驳回事件ID | AT1: 驳回人 | AU1: 驳回原因
A2: 主机遭受web攻击 | B2: 中 | C2: 172.16.5.31 | D2: 外部威胁>web攻击 | E2: 已忽略（自动） | F2: 69b935d28ccf7e4eb1e4b944 | G2: 价值交付三组 | I2: sta | J2: oa.haiheangroup.com:88/emp/api/log/record | K2: 自定义usecase、安全分析中台引擎 | L2: 46098.796 | M2: 46098.796 | N2: 李想 | P2: 中 | R2: 223.105.69.200 | S2: 172.16.5.31 | U2: T20240118201716341 | V2: 服务内 (7*24H) | W2: 服务器 | X2: 上海园区MSS资产>泛微oa系统-应用服务器 | Y2: 郭永斌 | Z2: 46098.797 | AB2: 正常 | AD2: 失败 | AE2: 外-内 | AG2: 0天0时0分2秒 | AH2: 46098.797 | AM2: http | AO2: 全部未知 | AP2: 30min | AQ2: 46098.817 | AR2: 高可信
A3: 泛微OA后台管理页面暴露在公网 | B3: 低 | C3: 172.16.5.31 | D3: 脆弱性>敏感页面暴露 | E3: 已忽略（自动） | F3: 69b91cf4741d8d2486b94e68 | G3: 价值交付三组 | I3: sta | J3: oa.haiheangroup.com:8788/api/hrm/login/checkLogin | K3: 脆弱性、安全分析中台引擎 | L3: 46098.722 | M3: 46098.79 | N3: 姚金鑫 | P3: 低 | R3: 27.17.5.74 | S3: 172.16.5.31 | U3: T20221108090812259 | V3: 服务内 (7*24H) | W3: 服务器 | X3: 上海园区MSS资产>泛微oa系统-应用服务器 | Y3: 郭永斌 | Z3: 46098.723 | AA3: MSSP | AB3: 正常 | AD3: 成功 | AE3: 外-内 | AG3: 0天0时0分1秒 | AH3: 46098.723 | AK3: 54470 | AL3: 8788 | AM3: http | AN3: 67f76f1630da8824bbe523c5 | AO3: 全部未知 | AP3: 30min | AQ3: 46098.744 | AR3: 中可信
A4: 弱口令登录成功 | B4: 中 | C4: 172.16.5.31 | D4: 脆弱性>账号安全 | E4: 已忽略（自动） | F4: 69b80810444e5db4916e0a76 | G4: 价值交付三组 | I4: sta | J4: oa.haiheangroup.com:8788/api/hrm/login/checkLogin | K4: 安全分析中台引擎 | L4: 46097.902 | M4: 46098.79 | N4: 李想 | P4: 中 | R4: 60.209.202.180 | S4: 172.16.5.31 | U4: T20240625103030429 | V4: 服务内 (7*24H) | W4: 服务器 | X4: 上海园区MSS资产>泛微oa系统-应用服务器 | Y4: 郭永斌 | Z4: 46097.902 | AA4: MSSP | AB4: 正常 | AD4: 成功 | AE4: 外-内 | AG4: 0天0时0分1秒 | AH4: 46097.902 | AM4: http | AN4: 665f1228c5c67f4645b0a64b | AO4: 全部未知 | AP4: 30min | AQ4: 46097.923 | AR4: 中可信
A5: 主机遭受web攻击 | B5: 中 | C5: 172.16.5.31 | D5: 外部威胁>web攻击 | E5: 已忽略（自动） | F5: 69b91b6553b3105a30007dec | G5: 价值交付三组 | I5: af | J5: oa.haiheangroup.com:8788/api/systemViewLog/home/InsertSystemPageViewLog | K5: 自定义usecase、安全分析中台引擎 | L5: 46098.718 | M5: 46098.724 | N5: 安宏祥 | P5: 中 | R5: 219.147.9.110 | S5: 172.16.5.31 | U5: T20240118201716341 | V5: 服务内 (7*24H) | W5: 服务器 | X5: 上海园区MSS资产>泛微oa系统-应用服务器 | Y5: 郭永斌 | Z5: 46098.718 | AB5: 正常 | AD5: 失败 | AE5: 外-内 | AG5: 0天0时0分3秒 | AH5: 46098.718 | AM5: http | AO5: 全部未知 | AP5: 30min | AQ5: 46098.739 | AR5: 高可信
A6: 主机存在感染挖矿家族minepool | B6: 低 | C6: 192.168.1.7 | D6: 内部威胁>挖矿 | E6: 已忽略（自动） | F6: 69b7b5e2a56cdc6fb96705fd | G6: 价值交付三组 | I6: XDR_af | J6: waterhole.io | K6: APEX-GPT引擎 | L6: 46048.609 | M6: 46098.722 | P6: 高 | R6: 192.168.1.7 | S6: 219.147.1.66 | T6: - | U6: 8eae36450000 | V6: 服务外 | W6: 终端 | X6: 天津园区MSS资产>青岛办公pc或监控 | Y6: 郭永斌 | Z6: 46097.659 | AA6: MSSP | AB6: 正常 | AD6: 失陷 | AE6: 内-外 | AG6: 0天0时0分5秒 | AH6: 46097.659 | AK6: 51847 | AL6: 53 | AM6: udp | AN6: 66ac46f31af7a614fd65393e | AP6: 30min | AQ6: 46097.68 | AR6: 高可信
A7: 泛微OA后台管理页面暴露在公网 | B7: 低 | C7: 172.16.5.31 | D7: 脆弱性>敏感页面暴露 | E7: 已忽略（自动） | F7: 69b7c941741d8d2486b92737 | G7: 价值交付三组 | I7: sta | J7: oa.haiheangroup.com:8788/api/hrm/login/checkLogin | K7: 脆弱性、安全分析中台引擎 | L7: 46097.715 | M7: 46098.71 | N7: 安宏祥 | P7: 低 | R7: 219.147.9.110 | S7: 172.16.5.31 | U7: T20221108090812259 | V7: 服务内 (7*24H) | W7: 服务器 | X7: 上海园区MSS资产>泛微oa系统-应用服务器 | Y7: 郭永斌 | Z7: 46097.716 | AA7: MSSP | AB7: 正常 | AD7: 成功 | AE7: 外-内 | AG7: 0天0时0分2秒 | AH7: 46097.716 | AK7: 62355 | AL7: 8788 | AM7: http | AN7: 67f76f1630da8824bbe523c5 | AO7: 全部未知 | AP7: 30min | AQ7: 46097.737 | AR7: 中可信
A8: 弱口令登录成功 | B8: 中 | C8: 172.16.5.31 | D8: 脆弱性>账号安全 | E8: 已忽略（自动） | F8: 69b8aab18ccf7e4eb1e4a655 | G8: 价值交付三组 | I8: sta | J8: oa.haiheangroup.com:8788/api/hrm/login/checkLogin | K8: 安全分析中台引擎 | L8: 46098.383 | M8: 46098.705 | N8: 涂峰川 | P8: 中 | R8: 219.147.9.110 | S8: 172.16.5.31 | U8: T20240625103030429 | V8: 服务内 (7*24H) | W8: 服务器 | X8: 上海园区MSS资产>泛微oa系统-应用服务器 | Y8: 郭永斌 | Z8: 46098.384 | AA8: MSSP | AB8: 正常 | AD8: 成功 | AE8: 外-内 | AG8: 0天0时0分2秒 | AH8: 46098.384 | AM8: http | AN8: 665f1228c5c67f4645b0a64b | AO8: 全部未知 | AP8: 30min | AQ8: 46098.405 | AR8: 中可信
A9: 弱口令登录成功 | B9: 中 | C9: 172.16.5.31 | D9: 脆弱性>账号安全 | E9: 已忽略（自动） | F9: 69b91630a396910f1b778dc6 | G9: 价值交付三组 | I9: sta | J9: oa.haiheangroup.com:8788/api/hrm/login/checkLogin | K9: 安全分析中台引擎 | L9: 46098.702 | M9: 46098.702 | N9: 姚金鑫 | P9: 中 | R9: 223.105.69.206 | S9: 172.16.5.31 | U9: T20240625103030429 | V9: 服务内 (7*24H) | W9: 服务器 | X9: 上海园区MSS资产>泛微oa系统-应用服务器 | Y9: 郭永斌 | Z9: 46098.703 | AA9: MSSP | AB9: 正常 | AD9: 成功 | AE9: 外-内 | AG9: 0天0时0分3秒 | AH9: 46098.703 | AM9: http | AN9: 665f1228c5c67f4645b0a64b | AO9: 全部未知 | AP9: 30min | AQ9: 46098.724 | AR9: 中可信
A10: 主机遭受web攻击 | B10: 中 | C10: 172.16.5.31 | D10: 外部威胁>web攻击 | E10: 已忽略（自动） | F10: 69b9024944107df81566f917 | G10: 价值交付三组 | I10: af | J10: oa.haiheangroup.com:8788/api/systemViewLog/home/InsertSystemPageViewLog | K10: 自定义usecase、安全分析中台引擎 | L10: 46098.644 | M10: 46098.673 | N10: 姚金鑫 | P10: 中 | R10: 101.204.24.178 | S10: 172.16.5.31 | U10: T20240118201716341 | V10: 服务内 (7*24H) | W10: 服务器 | X10: 上海园区MSS资产>泛微oa系统-应用服务器 | Y10: 郭永斌 | Z10: 46098.644 | AB10: 正常 | AD10: 失败 | AE10: 外-内 | AG10: 0天0时0分8秒 | AH10: 46098.644 | AM10: http | AO10: 全部未知 | AP10: 30min | AQ10: 46098.665 | AR10: 高可信
A11: 弱口令登录成功 | B11: 中 | C11: 172.16.5.31 | D11: 脆弱性>账号安全 | E11: 已忽略（自动） | F11: 69b90b8da0e97d17dfae9512 | G11: 价值交付三组 | I11: sta | J11: oa.haiheangroup.com:8788/api/hrm/login/checkLogin | K11: 安全分析中台引擎 | L11: 46098.67 | M11: 46098.672 | N11: 安宏祥 | P11: 中 | R11: 27.17.5.74 | S11: 172.16.5.31 | U11: T20240625103030429 | V11: 服务内 (7*24H) | W11: 服务器 | X11: 上海园区MSS资产>泛微oa系统-应用服务器 | Y11: 郭永斌 | Z11: 46098.671 | AA11: MSSP | AB11: 正常 | AD11: 成功 | AE11: 外-内 | AG11: 0天0时0分10秒 | AH11: 46098.671 | AM11: http | AN11: 665f1228c5c67f4645b0a64b | AO11: 全部未知 | AP11: 30min | AQ11: 46098.692 | AR11: 中可信
A12: 弱口令登录成功 | B12: 中 | C12: 172.16.5.31 | D12: 脆弱性>账号安全 | E12: 已忽略（自动） | F12: 69b90ae9741d8d2486b94bf3 | G12: 价值交付三组 | I12: sta | J12: oa.haiheangroup.com:8788/api/hrm/login/checkLogin | K12: 安全分析中台引擎 | L12: 46098.669 | M12: 46098.669 | N12: 安宏祥 | P12: 中 | R12: 219.147.9.110 | S12: 172.16.5.31 | U12: T20240625103030429 | V12: 服务内 (7*24H) | W12: 服务器 | X12: 上海园区MSS资产>泛微oa系统-应用服务器 | Y12: 郭永斌 | Z12: 46098.669 | AA12: MSSP | AB12: 正常 | AD12: 成功 | AE12: 外-内 | AG12: 0天0时0分2秒 | AH12: 46098.669 | AM12: http | AN12: 665f1228c5c67f4645b0a64b | AO12: 全部未知 | AP12: 30min | AQ12: 46098.69 | AR12: 中可信
A13: 弱口令登录成功 | B13: 中 | C13: 172.16.5.31 | D13: 脆弱性>账号安全 | E13: 已忽略（自动） | F13: 69b90aa6b3f2e004b99c9a1d | G13: 价值交付三组 | I13: sta | J13: oa.haiheangroup.com:8788/api/hrm/login/checkLogin | K13: 安全分析中台引擎 | L13: 46098.668 | M13: 46098.668 | N13: 姚金鑫 | P13: 中 | R13: 219.147.9.110 | S13: 172.16.5.31 | U13: T20240625103030429 | V13: 服务内 (7*24H) | W13: 服务器 | X13: 上海园区MSS资产>泛微oa系统-应用服务器 | Y13: 郭永斌 | Z13: 46098.669 | AA13: MSSP | AB13: 正常 | AD13: 成功 | AE13: 外-内 | AG13: 0天0时0分9秒 | AH13: 46098.669 | AM13: http | AN13: 665f1228c5c67f4645b0a64b | AO13: 全部未知 | AP13: 30min | AQ13: 46098.689 | AR13: 中可信
A14: 弱口令登录成功 | B14: 中 | C14: 172.16.5.31 | D14: 脆弱性>账号安全 | E14: 已忽略（自动） | F14: 69b90a547497cd0e21ae9886 | G14: 价值交付三组 | I14: sta | J14: oa.haiheangroup.com:8788/api/hrm/login/checkLogin | K14: 安全分析中台引擎 | L14: 46098.667 | M14: 46098.667 | N14: 涂峰川 | P14: 中 | R14: 219.147.9.110 | S14: 172.16.5.31 | U14: T20240625103030429 | V14: 服务内 (7*24H) | W14: 服务器 | X14: 上海园区MSS资产>泛微oa系统-应用服务器 | Y14: 郭永斌 | Z14: 46098.668 | AA14: MSSP | AB14: 正常 | AD14: 成功 | AE14: 外-内 | AG14: 0天0时0分3秒 | AH14: 46098.668 | AM14: http | AN14: 665f1228c5c67f4645b0a64b | AO14: 全部未知 | AP14: 30min | AQ14: 46098.688 | AR14: 中可信
A15: 主机遭受web攻击 | B15: 中 | C15: 172.16.1.4 | D15: 外部威胁>web攻击 | E15: 已忽略（自动） | F15: 69b909bab3f2e004b99c99f4 | G15: 价值交付三组 | I15: af | J15: tdyy.haiheangroup.com:9443/fort/system;help/node_management/save_strategy | K15: 自定义usecase、安全分析中台引擎 | L15: 46098.666 | M15: 46098.666 | P15: 中 | R15: 223.104.43.33 | S15: 172.16.1.4 | U15: T20240118201716341 | V15: 服务外 | W15: 未知 | X15: 上海园区MSS资产>深信服堡垒机 | Y15: 郭永斌 | Z15: 46098.666 | AA15: MSSP | AB15: 正常 | AD15: 待研判 | AE15: 外-内 | AG15: 0天0时0分5秒 | AH15: 46098.666 | AM15: https | AN15: 66ac46f31af7a614fd65393e | AO15: 全部未知 | AP15: 30min | AQ15: 46098.687 | AR15: 高可信
A16: 主机遭受web攻击 | B16: 中 | C16: 172.16.5.31 | D16: 外部威胁>web攻击 | E16: 已忽略（自动） | F16: 69b906c944107df81566f9d3 | G16: 价值交付三组 | I16: af | J16: oa.haiheangroup.com:8788/api/integration/workflowflow/getInterfaceRegisterDMLAddForm | K16: 自定义usecase、安全分析中台引擎 | L16: 46098.657 | M16: 46098.657 | N16: 安宏祥 | P16: 中 | R16: 60.175.115.106 | S16: 172.16.5.31 | U16: T20240118201716341 | V16: 服务内 (7*24H) | W16: 服务器 | X16: 上海园区MSS资产>泛微oa系统-应用服务器 | Y16: 郭永斌 | Z16: 46098.657 | AB16: 正常 | AD16: 失败 | AE16: 外-内 | AG16: 0天0时0分5秒 | AH16: 46098.657 | AM16: http | AO16: 全部未知 | AP16: 30min | AQ16: 46098.678 | AR16: 高可信
A17: 主机遭受web攻击 | B17: 中 | C17: 192.168.22.23 | D17: 外部威胁>web攻击 | E17: 已忽略（自动） | F17: 69b8fed044107df81566f89e | G17: 价值交付三组 | I17: af | J17: 60.28.99.74:8443/fort/system;help/node_management/save_strategy | K17: 自定义usecase、安全分析中台引擎 | L17: 46098.633 | M17: 46098.636 | P17: 中 | R17: 27.10.117.145 | S17: 192.168.22.23 | T17: 127.0.0.1 | U17: T20240118201716341 | V17: 服务外 | W17: 服务器 | X17: 天津园区MSS资产>天津堡垒机 | Y17: 郭永斌 | Z17: 46098.634 | AA17: MSSP | AB17: 正常 | AD17: 失败 | AE17: 外-内 | AG17: 0天0时0分1秒 | AH17: 46098.634 | AM17: https | AN17: 66ac46f31af7a614fd65393e | AO17: 全部未知 | AP17: 30min | AQ17: 46098.654 | AR17: 高可信
A18: 主机遭受web攻击 | B18: 中 | C18: 172.16.5.31 | D18: 外部威胁>web攻击 | E18: 已忽略（自动） | F18: 69b8fa66a0e97d17dfae92bc | G18: 价值交付三组 | I18: af | J18: oa.haiheangroup.com:8788/api/systemViewLog/home/InsertSystemPageViewLog | K18: 自定义usecase、安全分析中台引擎 | L18: 46098.62 | M18: 46098.624 | N18: 姚金鑫 | P18: 中 | R18: 60.30.190.26 | S18: 172.16.5.31 | U18: T20240118201716341 | V18: 服务内 (7*24H) | W18: 服务器 | X18: 上海园区MSS资产>泛微oa系统-应用服务器 | Y18: 郭永斌 | Z18: 46098.62 | AB18: 正常 | AD18: 失败 | AE18: 外-内 | AG18: 0天0时0分5秒 | AH18: 46098.62 | AM18: http | AO18: 全部未知 | AP18: 30min | AQ18: 46098.641 | AR18: 高可信
A19: 主机遭受web攻击 | B19: 中 | C19: 172.16.5.31 | D19: 外部威胁>web攻击 | E19: 已忽略（自动） | F19: 69b8f43c53b3105a300078aa | G19: 价值交付三组 | I19: af | J19: oa.haiheangroup.com:8788/api/systemViewLog/home/InsertSystemPageViewLog | K19: 自定义usecase、安全分析中台引擎 | L19: 46098.602 | M19: 46098.602 | N19: 姚金鑫 | P19: 中 | R19: 219.147.9.110 | S19: 172.16.5.31 | U19: T20240118201716341 | V19: 服务内 (7*24H) | W19: 服务器 | X19: 上海园区MSS资产>泛微oa系统-应用服务器 | Y19: 郭永斌 | Z19: 46098.602 | AB19: 正常 | AD19: 失败 | AE19: 外-内 | AG19: 0天0时0分4秒 | AH19: 46098.602 | AM19: http | AO19: 全部未知 | AP19: 30min | AQ19: 46098.623 | AR19: 高可信
A20: 主机存在感染僵尸网络家族malware | B20: 低 | C20: 192.168.1.138 | D20: 内部威胁>僵尸网络 | E20: 已忽略（自动） | F20: 69b8aaad120308c7598820d0 | G20: 价值交付三组 | I20: XDR_sta | J20: 137.220.135.153:5178 | K20: APEX-GPT引擎 | L20: 46077.375 | M20: 46098.599 | P20: 已失陷 | R20: 192.168.1.138 | S20: 137.220.135.153 | T20: - | U20: 2e3269e10000 | V20: 服务外 | W20: 服务器 | X20: 天津园区MSS资产>资产发现系统默认分组 | Y20: 郭永斌 | Z20: 46098.384 | AA20: MSSP | AB20: 正常 | AD20: 失陷 | AE20: 内-外 | AG20: 0天0时0分2秒 | AH20: 46098.384 | AK20: 55430 | AL20: 5178 | AM20: tcp | AN20: 66ac46f31af7a614fd65393e | AP20: 30min | AQ20: 46098.405 | AR20: 高可信
A21: 主机存在感染木马远控家族silverfox | B21: 低 | C21: 192.168.1.138 | D21: 内部威胁>木马 | E21: 已忽略（自动） | F21: 69b8aa6ec87d3abad4f8dfec | G21: 价值交付三组 | I21: XDR_af | J21: dashenbaba9.com | K21: APEX-GPT引擎 | L21: 46077.375 | M21: 46098.598 | P21: 已失陷 | R21: 192.168.1.138 | S21: 114.114.114.114 | T21: - | U21: 8ebd452b0000 | V21: 服务外 | W21: 服务器 | X21: 天津园区MSS资产>资产发现系统默认分组 | Y21: 郭永斌 | Z21: 46098.383 | AA21: MSSP | AB21: 正常 | AD21: 失陷 | AE21: 内-外 | AG21: 0天0时0分2秒 | AH21: 46098.384 | AK21: 61027 | AL21: 53 | AM21: dns | AN21: 66ac46f31af7a614fd65393e | AP21: 30min | AQ21: 46098.404 | AR21: 高可信
A22: 弱口令登录成功 | B22: 中 | C22: 192.168.0.109 | D22: 脆弱性>账号安全 | E22: 已忽略（自动） | F22: 69b8f1b210edc44512ac3668 | G22: 价值交付三组 | I22: sta | J22: 192.168.0.109:8017/login | K22: 安全分析中台引擎 | L22: 46098.592 | M22: 46098.592 | N22: 安宏祥 | P22: 中 | R22: 192.168.0.195 | S22: 192.168.0.109 | U22: T20240625103030429 | V22: 服务内 (7*24H) | W22: 服务器 | X22: 天津园区MSS资产>主应用服务器-1 | Y22: 郭永斌 | Z22: 46098.595 | AA22: MSSP | AB22: 正常 | AD22: 成功 | AE22: 内-内 | AG22: 0天0时0分1秒 | AH22: 46098.595 | AM22: http | AN22: 665f1228c5c67f4645b0a64b | AO22: 全部未知 | AP22: 30min | AQ22: 46098.615 | AR22: 中可信
A23: 弱口令登录成功 | B23: 中 | C23: 172.16.5.31 | D23: 脆弱性>账号安全 | E23: 已忽略（自动） | F23: 69b8e8970baeeb9910a7b2c3 | G23: 价值交付三组 | I23: sta | J23: oa.haiheangroup.com:8788/api/hrm/login/checkLogin | K23: 安全分析中台引擎 | L23: 46098.567 | M23: 46098.567 | N23: 李想 | P23: 中 | R23: 219.147.9.110 | S23: 172.16.5.31 | U23: T20240625103030429 | V23: 服务内 (7*24H) | W23: 服务器 | X23: 上海园区MSS资产>泛微oa系统-应用服务器 | Y23: 郭永斌 | Z23: 46098.568 | AA23: MSSP | AB23: 正常 | AD23: 成功 | AE23: 外-内 | AG23: 0天0时0分3秒 | AH23: 46098.568 | AM23: http | AN23: 665f1228c5c67f4645b0a64b | AO23: 全部未知 | AP23: 30min | AQ23: 46098.589 | AR23: 中可信
A24: 主机遭受web攻击 | B24: 中 | C24: 172.16.5.31 | D24: 外部威胁>web攻击 | E24: 已忽略（自动） | F24: 69b8e41eb3f2e004b99c94af | G24: 价值交付三组 | I24: sta | J24: oa.haiheangroup.com:8788/api/systemViewLog/home/InsertSystemPageViewLog | K24: 自定义usecase、安全分析中台引擎 | L24: 46098.554 | M24: 46098.554 | N24: 李想 | P24: 中 | R24: 122.190.135.5 | S24: 172.16.5.31 | U24: T20240118201716341 | V24: 服务内 (7*24H) | W24: 服务器 | X24: 上海园区MSS资产>泛微oa系统-应用服务器 | Y24: 郭永斌 | Z24: 46098.554 | AB24: 正常 | AD24: 失败 | AE24: 外-内 | AG24: 0天0时0分3秒 | AH24: 46098.554 | AM24: http | AO24: 全部未知 | AP24: 30min | AQ24: 46098.575 | AR24: 高可信
A25: 弱口令登录成功 | B25: 中 | C25: 172.16.5.31 | D25: 脆弱性>账号安全 | E25: 已忽略（自动） | F25: 69b8e40b741d8d2486b946aa | G25: 价值交付三组 | I25: sta | J25: oa.haiheangroup.com:8788/api/hrm/login/checkLogin | K25: 安全分析中台引擎 | L25: 46098.553 | M25: 46098.553 | N25: 李想 | P25: 中 | R25: 27.17.5.74 | S25: 172.16.5.31 | U25: T20240625103030429 | V25: 服务内 (7*24H) | W25: 服务器 | X25: 上海园区MSS资产>泛微oa系统-应用服务器 | Y25: 郭永斌 | Z25: 46098.554 | AA25: MSSP | AB25: 正常 | AD25: 成功 | AE25: 外-内 | AG25: 0天0时0分3秒 | AH25: 46098.554 | AM25: http | AN25: 665f1228c5c67f4645b0a64b | AO25: 全部未知 | AP25: 30min | AQ25: 46098.575 | AR25: 中可信
A26: 弱口令登录成功 | B26: 中 | C26: 172.16.5.31 | D26: 脆弱性>账号安全 | E26: 已忽略（自动） | F26: 69b8e00d444e5db4916e21de | G26: 价值交付三组 | I26: sta | J26: oa.haiheangroup.com:8788/api/hrm/login/checkLogin | K26: 安全分析中台引擎 | L26: 46098.542 | M26: 46098.542 | N26: 李想 | P26: 中 | R26: 60.27.106.163 | S26: 172.16.5.31 | U26: T20240625103030429 | V26: 服务内 (7*24H) | W26: 服务器 | X26: 上海园区MSS资产>泛微oa系统-应用服务器 | Y26: 郭永斌 | Z26: 46098.542 | AA26: MSSP | AB26: 正常 | AD26: 成功 | AE26: 外-内 | AG26: 0天0时0分3秒 | AH26: 46098.542 | AM26: http | AN26: 665f1228c5c67f4645b0a64b | AO26: 全部未知 | AP26: 30min | AQ26: 46098.563 | AR26: 中可信
