Workbook

Sheet 可视化看板

Sheet 数据统计
B1: 注：填充色为浅黄色的单元格需要手动查找数据填充，其余数据从MSSP平台导出底数据后覆盖子表内容，再更新单元格L1和M1自动按照统计周期计算结果； | H1: 当前时间 | I1: =TODAY() -> 46286 | J1: 徐湃有限公司 | K1: 统计周期 | L1: 45870 | M1: 46098
B3: P8 | C3: TOP3的核心业务系统 | D3: 手写-系统1 | F3: 威胁运营 | K3: 重保时间周期 | L3: 护网时间 | M3: 2026/03/01-2026/03/30 | N3: 护网，可选，固定此格，来源提示词
D4: 手写-系统2 | F4: 安全策略调优数量 | G4: 13 | L4: 元旦 | M4: 2026/01/01-2026/01/03 | N4: 其余假日：时间范围 中秋、国庆。元旦、春节、清明、五一、端午
D5: 手写-系统3 | F5: 威胁告警总 | G5: 14 | L5: 春节 | M5: 2026/02/15-2026/02/23
C6: 安全风险总数 | D6: 1 | F6: 核心系统威胁告警数量 | G6: 15 | H6: 16 | I6: 17
B7: TOP3核心资产漏洞分布 | C7: =D3 -> 手写-系统1 | D7: 手写 | F7: 威胁平均遏制时间 | G7: 16
C8: =D4 -> 手写-系统2 | D8: 手写 | F8: 安全事件总数 | G8: 17
C9: =D5 -> 手写-系统3 | D9: 手写 | F9: 事件平均响应时长 | G9: 18
C10: 高危可利用漏洞数 | D10: 2 | E10: 提取管理员弱口令数量 | F10: 核心系统事件数量 | G10: 19
C11: 管理员弱口令数量 | D11: 3
C12: 最新漏洞影响资产数 | D12: 4 | E12: 提取事件表中未公开威胁类型工单中受影响资产的IP数量，1.1.1.1,2.2.2.2.这就是两个 | F12: 核心系统风险总数 | G12: 20
C13: 已闭环风险数 | D13: 5 | F13: 核心系统风险闭环风险数 | G13: 21
C14: 已防护漏洞数 | D14: 6 | F14: 核心系统威胁事件总数 | G14: 22
C15: 已修复漏洞数 | D15: 7 | E15: 提取事件表中未公开威胁类型工单中受影响资产的IP数量
C16: 已处置弱口令数量 | D16: 8 | F16: 业务系统数量 | G16: 23
C17: 受影响的最新漏洞数 | D17: 9 | F17: 服务器资产数量 | G17: 24
B18: 系统X已闭环风险数 | C18: 10 | D18: 11 | E18: 12 | F18: PC资产数量 | G18: 25
B20: P14 | C20: 被通报风险总数 | D20: 1 | E20: 手写
B21: 通报风险应对 | C21: 外联通报风险次数 | D21: 2 | F21: 漏扫次数 | G21: 4
C22: 安全策略调优数量 | D22: 3 | E22: 手写 | F22: 已闭环漏洞总数 | G22: 5
C23: 已拦截外联次数 | D23: =COUNTIFS(资产漏洞表!P:P,"已修复") -> 0 | F23: 已防护漏洞数 | G23: 6
C24: 恶意外联告警数 | D24: =COUNTIFS(资产漏洞表!P:P,"已防护") -> 0 | F24: 已修复漏洞数 | G24: 7
C25: 本次汇报周期被通报次数 | D25: 手写 | E25: 手写
B27: P16 | C27: 「重要时期安全日志数」 | D27: 10 | E27: 重保周期+重要节假日 | F27: 只统计安全告警日志，选择时间，取总数，超过六个月取不到
B28: 重要时期保障 | C28: 「重要时期告警数」 | D28: 11 | E28: 告警表在重保时间范围的
C29: 「重要时期事件数」 | D29: 12 | E29: 时间表在重保时间范围的
C30: 重大事故数 | D30: 手写
B32: P19 | C32: 资产覆盖率 | D32: 手写
C33: 威胁遏制率 | D33: 1 | E33: 默认100%
C34: 高危漏洞防护率 | D34: =COUNTIFS(资产漏洞表!E:E,"高危",资产漏洞表!P:P,"已防护")/COUNTIFS(资产漏洞表!E:E,"高危") -> 0
C35: 平均分析时间 | D35: =AVERAGEIFS(事件表!AZ:AZ,事件表!AZ:AZ,"<>",事件表!AW:AW,"已通告",事件表!A:A,"*事件*") -> 1.46
C36: 平均响应时间 | D36: =AVERAGEIFS(事件表!BA:BA,事件表!BA:BA,"<>",事件表!AW:AW,"已通告",事件表!A:A,"*事件*") -> 6.68
C37: 已闭环漏洞数量 | D37: =COUNTIFS(资产漏洞表!P:P,"*已*") -> 0
C38: 威胁和事件数量 | D38: =COUNTIFS(事件表!B:B,">="&L1,事件表!B:B,"<="&M1) -> 18
C39: 两名高级安全工程师成本 | D39: 手写
B48: P27 | C48: 安全事件总数 | D48: 事件平均响应时间 | E48: 事件平均处置时长 | F48: 事件闭环率
C49: =COUNTIFS(事件表!A:A,"*事件*",事件表!B:B,">="&L1,事件表!B:B,"<="&M1) -> 7 | D49: =AVERAGEIFS(事件表!BA:BA,事件表!BA:BA,"<>",事件表!AW:AW,"已通告",事件表!A:A,"*事件*") -> 6.68 | E49: =AVERAGEIFS(事件表!BC:BC,事件表!BC:BC,"<>",事件表!AW:AW,"已通告",事件表!A:A,"*事件*") -> 6955.7175 | F49: =(COUNTIFS(事件表!A:A,"*事件*",事件表!I:I,"*已*",事件表!B:B,">="&L1,事件表!B:B,"<="&M1)+COUNTIFS(事件表!A:A,"*事件*",事件表!I:I,"*不处置*",事件表!B:B,">="&L1,事件表!B:B,"<="&M1))/C49 -> 1
B51: 安全事件类型TOP5 | C51: 渗透框架 | D51: =COUNTIFS(事件表!C:C,C51,事件表!A:A,"*事件*") -> 2 | E51: 平均处置时间（分钟） | F51: 识别 | G51: =AVERAGEIFS(事件表!AZ:AZ,事件表!AZ:AZ,"<>",事件表!AW:AW,"已通告",事件表!A:A,"*事件*") -> 1.46
C52: 木马 | D52: =COUNTIFS(事件表!C:C,C52,事件表!A:A,"*事件*") -> 0 | F52: 响应 | G52: =AVERAGEIFS(事件表!BA:BA,事件表!BA:BA,"<>",事件表!AW:AW,"已通告",事件表!A:A,"*事件*") -> 6.68
C53: 代理工具 | D53: =COUNTIFS(事件表!C:C,C53,事件表!A:A,"*事件*") -> 0 | F53: 遏制 | G53: =AVERAGEIFS(事件表!BB:BB,事件表!BB:BB,"<>",事件表!AW:AW,"已通告",事件表!A:A,"*事件*") -> 6.68
...

Sheet 运营机制
B2: 风险管理
B3: 类别 | C3: 子类别 | D3: 服务执行机制 | E3: 用户方配合事项 | F3: 执行标准
B4: 互联网暴露面 | C4: 暴露面分析 | D4: 首次全面梳理 常态化监测扫描，每周轮询扫描一次 | E4: 确认暴露面是否为业务需要，对不需要的暴露面做访问权限收敛 | F4: 每季度/次
C5: 攻击面分析 | D5: 首次全面梳理外部攻击面及暴露面弱点 常态化监测扫描，每两周周轮询扫描一次 | E5: 对外部暴露面存在的业务弱点进行修复加固 | F5: 每半年/次
C6: 敏感数据泄露监测 | D6: 采用网络监测手段实时爬取暗网等平台是否存在单位相关的关键字数据信息，检测到后实时告警推送预警 | E6: 对异常数据外泄采取应对措施，降低影响 | F6: 7*24实时预警
B7: 漏洞管理 | C7: 互联网资产漏洞 | D7: 高危可利用：每季度针对服务器操作系统和应用程序执行一次漏洞扫描，验证漏洞的利用危害和业务影响 | E7: AF防护，针对AF无法防护的需要用户业务侧修复漏洞； 分发漏洞工单到业务系统维护方，开展漏洞修复和闭环跟进 | F7: 每季度/次
D8: 低可利用漏洞：每季度针对服务器操作系统和应用程序执行一次漏洞扫描，整理漏洞优先级 | E8: 针对有条件修复的漏洞定期进行补丁修复；修改系统配置或访问权限降低漏洞被利用的风险 | F8: 每季度/次
C9: 内网资产漏洞 | D9: 高危可利用：每季度针对服务器操作系统和应用程序执行一次漏洞扫描，整理漏洞优先级 | E9: AF防护，针对AF无法防护的需要用户业务侧修复漏洞； 分发漏洞工单到业务系统维护方，开展漏洞修复和闭环跟进 | F9: 每季度/次
D10: 低可利用漏洞：每季度针对服务器操作系统和应用程序执行一次漏洞扫描，整理漏洞优先级 | E10: 针对有条件修复的漏洞定期进行补丁修复；修改系统配置或访问权限降低漏洞被利用的风险 | F10: 每季度/次
B11: 业务弱点 | C11: 管理员弱密码 | D11: 主动探测：定期TSS扫描； 被动监测：实时推送工单，及时修改密码加固 | E11: 对发现的弱密码进行修改，制定/优化应用系统密码规则 | F11: 7*24实时预警
C12: 互联网系统弱密码 | D12: 被动监测：通过访问流量监测，发现后试试告警，通告用户方可及时修改强密码及密码规则； 主动探测：每季度执行一次互联网弱密码扫描 | E12: 对发现的弱密码进行修改，制定/优化应用系统密码规则 | F12: 7*24实时预警
C13: 内网普通用户弱密码 | D13: 被动监测：通过访问流量监测，发现后试试告警，通告用户方可及时修改强密码及密码规则； | E13: 对发现的弱密码进行修改，制定/优化应用系统密码规则 | F13: 每周/次
B14: 威胁运营
C15: 重大威胁 | D15: 定义：攻击者对内网发起的有组织，有预谋的持续性网络攻击（如 APT、新型威胁等） 7*24小时持续监测，发现有效威胁实时响应，遏制影响； | E15: 如发生业务行为命中安全规则被判定为攻击行为，封堵了源IP后造成业务访问异常时，反馈至服务群，解除封锁 | F15: 7*24实时处置
C16: 一般威胁 | D16: 定义：攻击者发起网络安全攻击，但是对业务未造成任何影响 7*24小时持续监测，发现有效威胁实时响应，遏制影响； | E16: 如发生业务行为命中安全规则被判定为攻击行为，封堵了源IP后造成业务访问异常时，反馈至服务群，解除封锁 | F16: 7*24实时处置
C17: 威胁预防 | D17: 定期开展安全设备策略/规则库检查，确保安全基础设施有效运行 | E17: 对存在风险的安全策略配合追溯原因和评估改进策略的可行性 | F17: 每月/次
B19: 闭环管理
B20: ①抑制：限制攻击或破坏涉及的范围，降低潜在的损失 ②调查：充足的举证信息 ③溯源：详细完整的入侵路径 ④处置：已发现问题的解决 ⑤加固：杜绝问题再次发生 | J20: 事件/告警分级定义标准
B21: 事件类型 | C21: 判断特征 | D21: 事件定级 | E21: 响应与闭环预案 | J21: 威胁及事件等级 | K21: 等级描述 | L21: 等级示例 | M21: SLA要求 | N21: 闭环要求
B22: 网络攻击 | C22: 攻击成功（例：Webshell上传成功） | D22: 重大事件 | E22: 抑制：联动AF封堵攻击源IP、隔离主机可疑进程或被上传的文件； 调查：关联日志分析攻击影响范围，对入侵成功的主机上机排查攻击动作痕迹和残余风险； 溯源：上机排查主机日志，结合流量日志还原攻击路径，找到入侵源头 处置：清除主机恶意文件/进程，恢复主机网络权限； 加固：针对入侵源头利用的漏洞点修复加固，加强安全策略配置 | J22: 重大事故 （对标国家标准I级事件） | K22: 因安全事件造成单位网络较大面积中断或主营业务系统较大面积瘫痪，影响系统重要客户的正常业务工作、对单位造成重大经济损失的或产生较严重不良社会影响： 1、网络较大面积中断：因网络中断，造成单位内半数以上部门不能正常使用一个及以上主营业务系统，持续时间超过 12 小时以上； 2、主营业务系统较大面积瘫痪：因系统主要功能不可用，造成单位内半数以上部门不能正常使用一个及以上主营业务系统，系统瘫痪时间 12 个小时以上。 | L22: 1、网络攻击类 外部攻击成功（webshell后门上传/远程命令执行/反序列化命令执行/远程漏洞利用成功等）且造成业务中断或关键业务数据丢失，影响重大的 2、病毒木马类 如加密勒索软件/webshell后门/黑链/主机存在恶意命令执行等事件发生，对业务连续性造成恶劣影响或产生勒索赔偿等重大损失的 | M22: 启用应急响应机制，工作时间15分钟，非工作时间30分钟之内云端专家进行响应，默认由专家团队进行远程协助解决，如远程无法解决的则采用最快的交通工具，省会2小时内上门处置，省内8小时内上门处置。 | N22: 抑制-->调查-->溯源-->处置-->加固
C23: 攻击失败（例：外网主机对内网主机发起一对多攻击） | D23: 重大威胁 | E23: 抑制（处置）：联动AF封堵攻击源IP | J23: 重大事件 （对标国家标准II级和III级事件） | K23: 因安全事件造成单位主营业务系统中断、敏感数据泄密，信息系统发布和传播系统发生篡改，影响系统部分客户的正常业务工作，或者被监管或主管单位通报，对单位造成较小损失或产生较小不良社会影响的。 | L23: 1、网络攻击类 1）外部攻击成功（webshell后门上传/远程命令执行/反序列化命令执行/远程漏洞利用成功/其他符合该等级的事件） 2）内部横向或内对外攻击成功（RDP暴力破解/系统命令执行/远程命令执行/其他符合该等级的事件） 2、病毒木马类 1）加密勒索软件/webshell后门/黑链/主机存在恶意命令执行/其他符合该等级的事件 | M23: 通告时间：从安全日志分析研判到通告，用时<30min 遏制影响时间：遏制影响时间<1h 准确率：安全事件经过人工确认后，准确率达到99% 闭环率：100% | N23: 抑制-->调查-->溯源-->处置-->加固
B24: 病毒木马 | C24: 感染型病毒（例：勒索病毒感染） | D24: 重大事件 | E24: 抑制：联动AF封堵外联目的IP/域名、联动EDR隔离主机可疑文件或主机网络权限 调查：联动EDR执行全盘查杀，关联主机流量侧行为日志调查扩散的影响范围 溯源：结合网络流量日志和主机操作日志，查明病毒文件上传途径 处置：清除主机病毒文件 加固：针对病毒文件上传途径做好安全加固（漏洞修复/加强密码策略/提高人员安全意识） | J24: 一般事件 （对标国家标准IV级事件） | K24: 因安全事件导致的内网小范围出现的网络延时或故障，信息系统功能缺陷或者短暂不可用，导致个别用户或者业务受影响等技术层面的事件，但是这些事件没有带来实际的损失和影响。 | L24: 1、网络攻击类 1）外部攻击成功（主机收到垃圾邮件/方法过滤/目录遍历攻击/过滤HTTP出错页面/其他符合该等级的事件） 2）内部横向或内对外攻击失败（漏洞利用攻击/SQL注入攻击/SMB暴力破解/其他符合该等级的事件） 2、病毒木马类 1）如僵尸网络/木马病毒/挖矿病毒/恶意文件/其他符合该等级的事件 | M24: 通告时间：从安全日志分析研判到通告，用时<30min 遏制影响时间：遏制影响时间<4h 准确率：安全事件经过人工确认后，准确率达到99% 闭环率：100% | N24: 抑制-->调查-->处置
C25: 非感染型病毒（例：主机访问黑客工具C2地址） | D25: 一般事件 | E25: 抑制：联动AF封堵外联目的IP/域名、联动EDR隔离主机可疑文件或主机网络权限 调查：联动EDR执行全盘查杀，关联主机流量侧行为日志调查扩散的影响范围 处置：清除主机病毒文件 | J25: 重大威胁 | K25: 攻击者对内网发起的有组织，有预谋的持续性网络攻击（如 APT） | L25: 1、网络攻击类 1）外部攻击失败（如APT攻击/持续性攻击） | M25: 通告时间：从安全日志分析研判到通告，用时<1h 遏制影响时间：遏制影响时间<1h 准确率：安全事件经过人工确认后，准确率达到99% 闭环率：100% | N25: 抑制-->处置
B26: 脆弱性利用 | C26: 漏洞（例：Shiro反序列化漏洞） | D26: 重大事件 | E26: 抑制：联动AF封堵攻击源IP 调查：查明主机是否存在对应利用的漏洞，核实是否存在被利用成功的痕迹 加固：加固漏洞补丁以及安全防护策略 | J26: 一般威胁 | K26: 攻击者对内网发起网络安全攻击，但是对业务未造成任何影响 | L26: 1、网络攻击类 1）外部攻击失败（如网站扫描/端口扫描/webshell上传/SQL注入攻击/其他符合该等级的事件） | M26: 通告时间：从安全日志分析研判到通告，用时<2h 遏制影响时限：遏制影响时间<4h 准确率：安全事件经过人工确认后，准确率达到99% 闭环率：100% | N26: 抑制
C27: 弱密码 | D27: 重大威胁 | E27: 调查：针对互联网用户和管理员账户弱密码登录成功的，实时通告预警，核实是否为用户正常登录,如为用户正常登录则提醒修改强密码，如非用户登录则提醒用户立即修改密码或禁用账户； 加固：立即修改单用户密码，在应用系统层面加强密码规则
B28: 业务连续性 | C28: 基础环境异常：安全组件日志无法同步或同步时延增大 | D28: 一般事件 | E28: 调查：查明组件是否运行正常，安全策略和日志是否有效 处置：针对安全设备存在的问题协调产品售后支持解决
C29: 业务访问中断：网站无法访问、设备接入云端平台离线 | D29: 重大事件 | E29: 调查：查明是否为网络中断或对应系统软件/硬件工作异常，及时通告预警； 处置：排除故障，恢复业务

Sheet 暴露面
A1: 服务内容 | B1: 资产类型 | C1: 类型 | D1: 子类型 | E1: 总数 | F1: 影子资产数
A2: 互联网暴露面 | B2: 基础资产 | C2: 域名资产 | D2: 根域名资产 | E2: 1 | F2: 0
D3: 子域名资产 | E3: 7 | F3: 0
C4: IP资产 | D4: IP资产 | E4: 3 | F4: 2
C5: 端口资产 | D5: 端口资产 | E5: 27 | F5: 26
C6: WEB资产 | D6: WEB资产 | E6: 20 | F6: 19
C7: 非WEB资产 | D7: 非WEB资产 | E7: 7 | F7: 7
C8: 网络&安全设备 | D8: 网络&安全设备 | E8: 4 | F8: 4
C9: 云类资产 | D9: 云类资产 | E9: 0 | F9: 0
C10: SSL证书 | D10: SSL证书 | E10: 27 | F10: /
B11: 移动端资产 | C11: APP | D11: APP | E11: 0 | F11: /
C12: 公众号 | D12: 公众号 | E12: 0 | F12: /
C13: 小程序 | D13: 小程序 | E13: 0 | F13: /

Sheet 资产漏洞表
A1: 序号 | B1: 漏洞名称 | C1: 扫描方式 | D1: 漏洞类型 | E1: 漏洞等级 | F1: 是否可利用 | G1: 防护规则 | H1: 业务系统 | I1: 负责人 | J1: 受影响主机/位置（系统导出） | K1: IP（手动分列增加） | L1: 端口 | M1: 版本号 | N1: 内/外网（刷新资产表公式匹配） | O1: 修复优先级 | P1: 跟进状态 | Q1: 备注信息 | R1: 来源 | S1: 发现时间 （填充此单元格为粉红色代表是最近扫描新增漏洞） | T1: 更新时间 | U1: 漏洞危害 | V1: 解决方案 | W1: 参考资料
A2: 1 | B2: SSH Diffie-Hellman 模数 <= 1024 位 (Logjam)(CVE-2015-4000) | C2: 版本比较 | D2: 系统漏洞 | E2: 低危 | F2: 否 | G2: 无效 | H2: XX1 | I2: 未知责任人 | J2: 192.168.9.20 | K2: 192.168.9.20 | L2: 22 | M2: - | N2: =_xlfn.XLOOKUP(K2,资产表!C:C,资产表!AG:AG,“”) -> #NAME? | O2: 建议修复 | P2: 处置中 | Q2: - | R2: TSS | S2: 45513.004 | T2: 46004.018 | U2: 这允许攻击者恢复明文或可能违反连接的完整性。 | V2: 重新配置服务以使用唯一的、2048 位或更高位数的 Diffie-Hellman moduli。 | W2: https://weakdh.org/ https://stribika.github.io/2015/01/04/secure-secure-shell.html https://www.cnnvd.org.cn/home/globalSearch?keyword=CNNVD-201505-428 http://www.securityfocus.com/bid/74733 http://www.securityfocus.com/bid/91787
A3: 2 | B3: SSH Diffie-Hellman 模数 <= 1024 位 (Logjam)(CVE-2015-4000) | C3: 版本比较 | D3: 系统漏洞 | E3: 低危 | F3: 否 | G3: 无效 | H3: XX2 | I3: 未知责任人 | J3: 192.168.9.220 | K3: 192.168.9.220 | L3: 22 | M3: - | N3: =_xlfn.XLOOKUP(K3,资产表!C:C,资产表!AG:AG,“”) -> #NAME? | O3: 建议修复 | P3: 处置中 | Q3: - | R3: TSS | S3: 45513.004 | T3: 46004.019 | U3: 这允许攻击者恢复明文或可能违反连接的完整性。 | V3: 重新配置服务以使用唯一的、2048 位或更高位数的 Diffie-Hellman moduli。 | W3: https://weakdh.org/ https://stribika.github.io/2015/01/04/secure-secure-shell.html https://www.cnnvd.org.cn/home/globalSearch?keyword=CNNVD-201505-428 http://www.securityfocus.com/bid/74733 http://www.securityfocus.com/bid/91787
A4: 3 | B4: 支持SSL 64位块大小的密码套件（SWEET32） | C4: 原理扫描 | D4: 系统漏洞 | E4: 高危 | F4: 否 | G4: 无效 | H4: XX3 | I4: 未知责任人 | J4: 172.20.34.80 | K4: 172.20.34.80 | L4: 3389 | M4: - | N4: =_xlfn.XLOOKUP(K4,资产表!C:C,资产表!AG:AG,“”) -> #NAME? | O4: 尽快修复 | P4: 处置中 | Q4: - | R4: TSS | S4: 45513.005 | T4: 46004.019 | U4: 具有足够资源的中间人攻击者可利用此漏洞,通过“birthday”攻击检测会在固定密码与已知纯文本之间泄露 XOR 的冲突,进而泄露密码文本（例如安全 HTTPS Cookie）,并可能导致劫持经认证的会话。 | V4: 参见《支持SSL 64位块大小的密码套件（SWEET32）-修复方案》 | W4: https://blog.csdn.net/weixin_46167705/article/details/123374139
A5: 4 | B5: 支持SSL 64位块大小的密码套件（SWEET32） | C5: 原理扫描 | D5: 系统漏洞 | E5: 高危 | F5: 否 | G5: 无效 | H5: XX4 | I5: 未知责任人 | J5: 172.20.34.78 | K5: 172.20.34.78 | L5: 3389 | M5: - | N5: =_xlfn.XLOOKUP(K5,资产表!C:C,资产表!AG:AG,“”) -> #NAME? | O5: 尽快修复 | P5: 处置中 | Q5: - | R5: TSS | S5: 45513.005 | T5: 46004.018 | U5: 具有足够资源的中间人攻击者可利用此漏洞,通过“birthday”攻击检测会在固定密码与已知纯文本之间泄露 XOR 的冲突,进而泄露密码文本（例如安全 HTTPS Cookie）,并可能导致劫持经认证的会话。 | V5: 参见《支持SSL 64位块大小的密码套件（SWEET32）-修复方案》 | W5: https://blog.csdn.net/weixin_46167705/article/details/123374139
A6: 5 | B6: 终端服务未使用网络级别身份验证（NLA） | C6: 原理扫描 | D6: 系统漏洞 | E6: 中危 | F6: 否 | G6: 无效 | H6: XX5 | I6: 未知责任人 | J6: 172.20.34.80 | K6: 172.20.34.80 | L6: 3389 | M6: - | N6: =_xlfn.XLOOKUP(K6,资产表!C:C,资产表!AG:AG,“”) -> #NAME? | O6: 建议修复 | P6: 处置中 | Q6: - | R6: TSS | S6: 45513.005 | T6: 46004.019 | U6: 未使用该认证的远程主机受攻击的风险等级高。 | V6: 参见《终端服务未使用网络级别身份验证（NLA）-修复方案》 | W6: https://blog.csdn.net/spring_is_coming/article/details/124982320
A7: 6 | B7: 终端服务未使用网络级别身份验证（NLA） | C7: 原理扫描 | D7: 系统漏洞 | E7: 中危 | F7: 否 | G7: 无效 | H7: XX6 | I7: 未知责任人 | J7: 172.20.34.70 | K7: 172.20.34.70 | L7: 3389 | M7: - | N7: =_xlfn.XLOOKUP(K7,资产表!C:C,资产表!AG:AG,“”) -> #NAME? | O7: 建议修复 | P7: 处置中 | Q7: - | R7: TSS | S7: 45513.005 | T7: 46004.019 | U7: 未使用该认证的远程主机受攻击的风险等级高。 | V7: 参见《终端服务未使用网络级别身份验证（NLA）-修复方案》 | W7: https://blog.csdn.net/spring_is_coming/article/details/124982320
A8: 7 | B8: SSL RC4 加密套件支持检测 (Bar Mitzvah) | C8: 原理扫描 | D8: 系统漏洞 | E8: 中危 | F8: 否 | G8: 无效 | H8: XX7 | I8: 未知责任人 | J8: 172.20.34.78 | K8: 172.20.34.78 | L8: 3389 | M8: - | N8: =_xlfn.XLOOKUP(K8,资产表!C:C,资产表!AG:AG,“”) -> #NAME? | O8: 建议修复 | P8: 处置中 | Q8: - | R8: TSS | S8: 45513.005 | T8: 46004.018 | U8: 攻击者可利用大量的密文推测明文，导致远程主机信息泄露。 | V8: 参见《SSL RC4 加密套件支持检测 (Bar Mitzvah)-修复方案》 | W8: https://www.imperva.com/docs/HII_Attacking_SSL_when_using_RC4.pdf https://blog.csdn.net/m0_54434140/article/details/126536929
A9: 8 | B9: 终端服务未使用网络级别身份验证（NLA） | C9: 原理扫描 | D9: 系统漏洞 | E9: 中危 | F9: 否 | G9: 无效 | H9: XX8 | I9: 未知责任人 | J9: 172.20.34.78 | K9: 172.20.34.78 | L9: 3389 | M9: - | N9: =_xlfn.XLOOKUP(K9,资产表!C:C,资产表!AG:AG,“”) -> #NAME? | O9: 建议修复 | P9: 处置中 | Q9: - | R9: TSS | S9: 45513.006 | T9: 46004.018 | U9: 未使用该认证的远程主机受攻击的风险等级高。 | V9: 参见《终端服务未使用网络级别身份验证（NLA）-修复方案》 | W9: https://blog.csdn.net/spring_is_coming/article/details/124982320

Sheet 资产表
A1: 序号 | B1: *业务名称 | C1: *IP/URL | D1: *业务等级 | E1: *服务类型 | F1: *资产类型 | G1: 业务责任人 | H1: 业务责任人邮箱 | I1: 业务责任人电话 | J1: Agent ID | K1: 存活状态 | L1: 资产标签 | M1: 服务/端口 | N1: 操作系统 | O1: 数据库 | P1: 中间件 | Q1: 开发语言 | R1: 开发框架 | S1: 应用/服务 | T1: AF可防护 | U1: EDR状态 | V1: 设备产商 | W1: 设备名称 | X1: 域名/URL | Y1: 应用品牌 | Z1: 应用版本 | AA1: 资产管理部门 | AB1: 资产责任人 | AC1: 资产责任人邮箱 | AD1: 资产责任人电话 | AE1: 扫描设备 | AF1: 分支 | AG1: 安全域 | AH1: 公网IP | AI1: 映射端口 | AJ1: 被映射端口
A2: 1 | B2: 系统1 | D2: 一般 | E2: 服务外 | F2: 物联网设备 | K2: 在线 | M2: dhanalakshmi(34567) soap(8899) unknown(9530,34561) http(80) rtsp(554) | N2: linux | P2: uc-httpd 1.0.0 | R2: gSOAP 2.7 | W2: NETSurveillance(Xiongmai-Cameras-and-Surveillance)(uc-httpd),DVR | AG2: 内网
A3: 2 | B3: 系统1 | D3: 一般 | E3: 服务外 | F3: 服务器 | K3: 在线 | M3: http(9000,5357,8585) pando-pub(7680) mysql(3306) msrpc(49667,49665,49670,135,49675,49664,49666,49669,49668) netbios-ssn(139) ms-wbt-server(4490) microsoft-ds(445) unknown(55064,5040) | N3: windows | O3: MySQL | P3: HttpSvr Microsoft-HTTPAPI 2.0 Apple-HFS | W3: HttpSvr,Microsoft-HTTPAPI,Apple-HFS | AG3: 内网
A4: 3 | B4: 系统1 | D4: 一般 | E4: 服务外 | F4: 终端 | K4: 在线 | M4: ssh(22) tcpwrapped(64443) | N4: linux | AG4: 内网
A5: 4 | B5: 系统2 | D5: 一般 | E5: 服务外 | F5: 服务器 | K5: 在线 | M5: http(80) ssl(443,4480,23031,23020) ssh(22) iscsi(3260) | N5: linux | P5: Apache httpd | W5: Sangfor-Enterprise Cloud Platform(Apache httpd) | Y5: Sangfor Technologies Inc.(Apache Software Foundation) | AG5: 内网
A6: 5 | B6: 系统2 | D6: 一般 | E6: 服务外 | F6: 终端 | K6: 在线 | AG6: 内网
A7: 6 | B7: 系统2 | D7: 一般 | E7: 服务外 | F7: 终端 | K7: 在线 | AG7: 内网
A8: 7 | B8: 系统3 | D8: 一般 | E8: 服务外 | F8: 终端 | K8: 在线 | AG8: 内网
A9: 8 | B9: 系统3 | D9: 一般 | E9: 服务外 | F9: 终端 | K9: 在线 | AG9: 内网
A10: 9 | B10: 系统3 | D10: 一般 | E10: 服务外 | F10: 终端 | K10: 在线 | M10: unknown(17561) ms-wbt-server(3389) tcpwrapped(53000) afs3-callback(7001) soap(52000) wap-wsp(9200) | N10: windows | AG10: 内网

Sheet 告警表
A1: 告警名称 | B1: 告警优先级 | C1: 主机IP | D1: 威胁类型 | E1: 告警状态 | F1: 告警ID | G1: 服务组 | H1: 主机名称 | I1: 设备 | J1: IOC | K1: 告警标签 | L1: 首次触发时间 | M1: 最近触发时间 | N1: 处理人 | O1: 事件ID | P1: 威胁等级 | Q1: 失陷情况 | R1: 源IP | S1: 目的IP | T1: XFF IP | U1: USECASE ID | V1: 服务类型 | W1: 资产类别 | X1: 资产信息 | Y1: 服务经理 | Z1: 创建时间 | AA1: 实际处理人 | AB1: 同步状态 | AC1: 场景标签 | AD1: 攻击结果 | AE1: 访问方向 | AF1: 确定性等级 | AG1: 审核时长 | AH1: 操作时间 | AI1: 任务名称 | AJ1: sip联动状态 | AK1: 源端口 | AL1: 目的端口 | AM1: 协议 | AN1: 审核id | AO1: 拦截情况 | AP1: Sla | AQ1: 审核到期时间 | AR1: 可信度 | AS1: 驳回事件ID | AT1: 驳回人 | AU1: 驳回原因
A2: 主机遭受web攻击 | B2: 中 | D2: 外部威胁>web攻击 | E2: 已忽略（自动） | F2: 69b935d28ccf7e4eb1e4b944 | G2: 价值交付三组 | I2: sta | J2: oa.haiheangroup.com:88/emp/api/log/record | K2: 自定义usecase、安全分析中台引擎 | L2: 46098.796 | M2: 46098.796 | N2: 李想 | P2: 中 | U2: T20240118201716341 | V2: 服务内 (7*24H) | W2: 服务器 | X2: 上海园区MSS资产>泛微oa系统-应用服务器 | Y2: 郭永斌 | Z2: 46098.797 | AB2: 正常 | AD2: 失败 | AE2: 外-内 | AG2: 0天0时0分2秒 | AH2: 46098.797 | AM2: http | AO2: 全部未知 | AP2: 30min | AQ2: 46098.817 | AR2: 高可信
A3: 泛微OA后台管理页面暴露在公网 | B3: 低 | D3: 脆弱性>敏感页面暴露 | E3: 已忽略（自动） | F3: 69b91cf4741d8d2486b94e68 | G3: 价值交付三组 | I3: sta | J3: oa.haiheangroup.com:8788/api/hrm/login/checkLogin | K3: 脆弱性、安全分析中台引擎 | L3: 46098.722 | M3: 46098.79 | N3: 姚金鑫 | P3: 低 | U3: T20221108090812259 | V3: 服务内 (7*24H) | W3: 服务器 | X3: 上海园区MSS资产>泛微oa系统-应用服务器 | Y3: 郭永斌 | Z3: 46098.723 | AA3: MSSP | AB3: 正常 | AD3: 成功 | AE3: 外-内 | AG3: 0天0时0分1秒 | AH3: 46098.723 | AK3: 54470 | AL3: 8788 | AM3: http | AN3: 67f76f1630da8824bbe523c5 | AO3: 全部未知 | AP3: 30min | AQ3: 46098.744 | AR3: 中可信
A4: 弱口令登录成功 | B4: 中 | D4: 脆弱性>账号安全 | E4: 已忽略（自动） | F4: 69b80810444e5db4916e0a76 | G4: 价值交付三组 | I4: sta | J4: oa.haiheangroup.com:8788/api/hrm/login/checkLogin | K4: 安全分析中台引擎 | L4: 46097.902 | M4: 46098.79 | N4: 李想 | P4: 中 | U4: T20240625103030429 | V4: 服务内 (7*24H) | W4: 服务器 | X4: 上海园区MSS资产>泛微oa系统-应用服务器 | Y4: 郭永斌 | Z4: 46097.902 | AA4: MSSP | AB4: 正常 | AD4: 成功 | AE4: 外-内 | AG4: 0天0时0分1秒 | AH4: 46097.902 | AM4: http | AN4: 665f1228c5c67f4645b0a64b | AO4: 全部未知 | AP4: 30min | AQ4: 46097.923 | AR4: 中可信
A5: 主机遭受web攻击 | B5: 中 | D5: 外部威胁>web攻击 | E5: 已忽略（自动） | F5: 69b91b6553b3105a30007dec | G5: 价值交付三组 | I5: af | J5: oa.haiheangroup.com:8788/api/systemViewLog/home/InsertSystemPageViewLog | K5: 自定义usecase、安全分析中台引擎 | L5: 46098.718 | M5: 46098.724 | N5: 安宏祥 | P5: 中 | U5: T20240118201716341 | V5: 服务内 (7*24H) | W5: 服务器 | X5: 上海园区MSS资产>泛微oa系统-应用服务器 | Y5: 郭永斌 | Z5: 46098.718 | AB5: 正常 | AD5: 失败 | AE5: 外-内 | AG5: 0天0时0分3秒 | AH5: 46098.718 | AM5: http | AO5: 全部未知 | AP5: 30min | AQ5: 46098.739 | AR5: 高可信
A6: 主机存在感染挖矿家族minepool | B6: 低 | D6: 内部威胁>挖矿 | E6: 已忽略（自动） | F6: 69b7b5e2a56cdc6fb96705fd | G6: 价值交付三组 | I6: XDR_af | J6: waterhole.io | K6: APEX-GPT引擎 | L6: 46048.609 | M6: 46098.722 | P6: 高 | T6: - | U6: 8eae36450000 | V6: 服务外 | W6: 终端 | X6: 天津园区MSS资产>青岛办公pc或监控 | Y6: 郭永斌 | Z6: 46097.659 | AA6: MSSP | AB6: 正常 | AD6: 失陷 | AE6: 内-外 | AG6: 0天0时0分5秒 | AH6: 46097.659 | AK6: 51847 | AL6: 53 | AM6: udp | AN6: 66ac46f31af7a614fd65393e | AP6: 30min | AQ6: 46097.68 | AR6: 高可信
A7: 泛微OA后台管理页面暴露在公网 | B7: 低 | D7: 脆弱性>敏感页面暴露 | E7: 已忽略（自动） | F7: 69b7c941741d8d2486b92737 | G7: 价值交付三组 | I7: sta | J7: oa.haiheangroup.com:8788/api/hrm/login/checkLogin | K7: 脆弱性、安全分析中台引擎 | L7: 46097.715 | M7: 46098.71 | N7: 安宏祥 | P7: 低 | U7: T20221108090812259 | V7: 服务内 (7*24H) | W7: 服务器 | X7: 上海园区MSS资产>泛微oa系统-应用服务器 | Y7: 郭永斌 | Z7: 46097.716 | AA7: MSSP | AB7: 正常 | AD7: 成功 | AE7: 外-内 | AG7: 0天0时0分2秒 | AH7: 46097.716 | AK7: 62355 | AL7: 8788 | AM7: http | AN7: 67f76f1630da8824bbe523c5 | AO7: 全部未知 | AP7: 30min | AQ7: 46097.737 | AR7: 中可信
A8: 弱口令登录成功 | B8: 中 | D8: 脆弱性>账号安全 | E8: 已忽略（自动） | F8: 69b8aab18ccf7e4eb1e4a655 | G8: 价值交付三组 | I8: sta | J8: oa.haiheangroup.com:8788/api/hrm/login/checkLogin | K8: 安全分析中台引擎 | L8: 46098.383 | M8: 46098.705 | N8: 涂峰川 | P8: 中 | U8: T20240625103030429 | V8: 服务内 (7*24H) | W8: 服务器 | X8: 上海园区MSS资产>泛微oa系统-应用服务器 | Y8: 郭永斌 | Z8: 46098.384 | AA8: MSSP | AB8: 正常 | AD8: 成功 | AE8: 外-内 | AG8: 0天0时0分2秒 | AH8: 46098.384 | AM8: http | AN8: 665f1228c5c67f4645b0a64b | AO8: 全部未知 | AP8: 30min | AQ8: 46098.405 | AR8: 中可信
A9: 弱口令登录成功 | B9: 中 | D9: 脆弱性>账号安全 | E9: 已忽略（自动） | F9: 69b91630a396910f1b778dc6 | G9: 价值交付三组 | I9: sta | J9: oa.haiheangroup.com:8788/api/hrm/login/checkLogin | K9: 安全分析中台引擎 | L9: 46098.702 | M9: 46098.702 | N9: 姚金鑫 | P9: 中 | U9: T20240625103030429 | V9: 服务内 (7*24H) | W9: 服务器 | X9: 上海园区MSS资产>泛微oa系统-应用服务器 | Y9: 郭永斌 | Z9: 46098.703 | AA9: MSSP | AB9: 正常 | AD9: 成功 | AE9: 外-内 | AG9: 0天0时0分3秒 | AH9: 46098.703 | AM9: http | AN9: 665f1228c5c67f4645b0a64b | AO9: 全部未知 | AP9: 30min | AQ9: 46098.724 | AR9: 中可信
A10: 主机遭受web攻击 | B10: 中 | D10: 外部威胁>web攻击 | E10: 已忽略（自动） | F10: 69b9024944107df81566f917 | G10: 价值交付三组 | I10: af | J10: oa.haiheangroup.com:8788/api/systemViewLog/home/InsertSystemPageViewLog | K10: 自定义usecase、安全分析中台引擎 | L10: 46098.644 | M10: 46098.673 | N10: 姚金鑫 | P10: 中 | U10: T20240118201716341 | V10: 服务内 (7*24H) | W10: 服务器 | X10: 上海园区MSS资产>泛微oa系统-应用服务器 | Y10: 郭永斌 | Z10: 46098.644 | AB10: 正常 | AD10: 失败 | AE10: 外-内 | AG10: 0天0时0分8秒 | AH10: 46098.644 | AM10: http | AO10: 全部未知 | AP10: 30min | AQ10: 46098.665 | AR10: 高可信
A11: 弱口令登录成功 | B11: 中 | D11: 脆弱性>账号安全 | E11: 已忽略（自动） | F11: 69b90b8da0e97d17dfae9512 | G11: 价值交付三组 | I11: sta | J11: oa.haiheangroup.com:8788/api/hrm/login/checkLogin | K11: 安全分析中台引擎 | L11: 46098.67 | M11: 46098.672 | N11: 安宏祥 | P11: 中 | U11: T20240625103030429 | V11: 服务内 (7*24H) | W11: 服务器 | X11: 上海园区MSS资产>泛微oa系统-应用服务器 | Y11: 郭永斌 | Z11: 46098.671 | AA11: MSSP | AB11: 正常 | AD11: 成功 | AE11: 外-内 | AG11: 0天0时0分10秒 | AH11: 46098.671 | AM11: http | AN11: 665f1228c5c67f4645b0a64b | AO11: 全部未知 | AP11: 30min | AQ11: 46098.692 | AR11: 中可信
A12: 弱口令登录成功 | B12: 中 | D12: 脆弱性>账号安全 | E12: 已忽略（自动） | F12: 69b90ae9741d8d2486b94bf3 | G12: 价值交付三组 | I12: sta | J12: oa.haiheangroup.com:8788/api/hrm/login/checkLogin | K12: 安全分析中台引擎 | L12: 46098.669 | M12: 46098.669 | N12: 安宏祥 | P12: 中 | U12: T20240625103030429 | V12: 服务内 (7*24H) | W12: 服务器 | X12: 上海园区MSS资产>泛微oa系统-应用服务器 | Y12: 郭永斌 | Z12: 46098.669 | AA12: MSSP | AB12: 正常 | AD12: 成功 | AE12: 外-内 | AG12: 0天0时0分2秒 | AH12: 46098.669 | AM12: http | AN12: 665f1228c5c67f4645b0a64b | AO12: 全部未知 | AP12: 30min | AQ12: 46098.69 | AR12: 中可信
A13: 弱口令登录成功 | B13: 中 | D13: 脆弱性>账号安全 | E13: 已忽略（自动） | F13: 69b90aa6b3f2e004b99c9a1d | G13: 价值交付三组 | I13: sta | J13: oa.haiheangroup.com:8788/api/hrm/login/checkLogin | K13: 安全分析中台引擎 | L13: 46098.668 | M13: 46098.668 | N13: 姚金鑫 | P13: 中 | U13: T20240625103030429 | V13: 服务内 (7*24H) | W13: 服务器 | X13: 上海园区MSS资产>泛微oa系统-应用服务器 | Y13: 郭永斌 | Z13: 46098.669 | AA13: MSSP | AB13: 正常 | AD13: 成功 | AE13: 外-内 | AG13: 0天0时0分9秒 | AH13: 46098.669 | AM13: http | AN13: 665f1228c5c67f4645b0a64b | AO13: 全部未知 | AP13: 30min | AQ13: 46098.689 | AR13: 中可信
A14: 弱口令登录成功 | B14: 中 | D14: 脆弱性>账号安全 | E14: 已忽略（自动） | F14: 69b90a547497cd0e21ae9886 | G14: 价值交付三组 | I14: sta | J14: oa.haiheangroup.com:8788/api/hrm/login/checkLogin | K14: 安全分析中台引擎 | L14: 46098.667 | M14: 46098.667 | N14: 涂峰川 | P14: 中 | U14: T20240625103030429 | V14: 服务内 (7*24H) | W14: 服务器 | X14: 上海园区MSS资产>泛微oa系统-应用服务器 | Y14: 郭永斌 | Z14: 46098.668 | AA14: MSSP | AB14: 正常 | AD14: 成功 | AE14: 外-内 | AG14: 0天0时0分3秒 | AH14: 46098.668 | AM14: http | AN14: 665f1228c5c67f4645b0a64b | AO14: 全部未知 | AP14: 30min | AQ14: 46098.688 | AR14: 中可信

Sheet 事件表
A1: 说明： 事件类型：一般威胁、重大威胁、一般事件、重大事件标签取平台导出的，补充类型名称即可； 设备离线类标签定义为业务连续性风险； 未公开威胁类标签定义为最新威胁。
A2: 事件类型 | B2: 事件创建时间 | C2: 类型 | D2: 事件名称 | E2: 主机IP | F2: 设备名称 | G2: 源IP | H2: 业务URL | I2: 状态 | J2: 服务组 | K2: 主机名称 | L2: XFF IP | M2: 设备类型 | N2: 类型（二级场景） | O2: 优先级 | P2: 处置建议 | Q2: 负责人 | R2: 未处置原因 | S2: 当前处理人 | T2: 资产类别 | U2: 资产信息 | V2: 威胁等级 | W2: 事件标签 | X2: 事件描述 | Y2: 事件ID | Z2: 服务类型 | AA2: 资产责任人 | AB2: 目的IP | AC2: 最近更新时间 | AD2: 组件检出时间 | AE2: 专家研判时间 | AF2: 事件遏制时间 | AG2: 事件闭环时间 | AH2: 影响范围 | AI2: 根因分析 | AJ2: 危害 | AK2: 外部反馈 | AL2: IOC | AM2: 服务经理 | AN2: 重新生成事件ID | AO2: 所属资产组 | AP2: 受影响资产 | AQ2: 备注 | AR2: 接受风险时间 | AS2: 通告时间 | AT2: 防护时间 | AU2: 应急标签 | AV2: 闭环时长 | AW2: 通告状态 | AX2: 实际通告时间 | AY2: 资产内网外网 | AZ2: 识别时长 | BA2: 响应时长 | BB2: 遏制时长 | BC2: 处置时长 | BD2: 闭环时长
A3: 业务连续性风险 | B3: 45891.387 | C3: 设备离线 | D3: EDR设备离线 | E3: 0.0.0.0 | I3: 已闭环 | J3: 价值交付三组 | M3: EDR | N3: 设备离线 | O3: 高 | S3: 郭永斌 | T3: 未知 | V3: 未知 | W3: 设备离线 | X3: 设备离线，请及时处理 | Z3: 服务内 (7*24H) | AC3: 45891.387 | AD3: 45891.384 | AQ3: 设备已检测到上线，自动关闭 | AY3: =VLOOKUP(E3,资产表!C:AG,31,0) -> #N/A | AZ3: =IF(A3<>"最新威胁",ROUND((B3-AD3)*24*60,2),"") -> 4.77 | BA3: =IF(A3<>"最新威胁",IF(ISBLANK(AX3),IF(ISBLANK(AE3),ROUND((AC3-B3)*24*60,2),ROUND((AE3-B3)*24*60,2)),ROUND((AX3-B3)*24*60,2)),"") -> 0.02 | BB3: =IF(A3<>"最新威胁",IF(ISBLANK(AX3),"",ROUND((AX3-B3)*24*60,2)),"") | BC3: =IF(A3<>"最新威胁",IF(ISBLANK(AF3),ROUND((AC3-B3)*24*60,2),ROUND((AF3-B3)*24*60,2)),"") -> 0.02 | BD3: =IF(A3<>"最新威胁",IF(ISBLANK(AG3),ROUND((AC3-B3)*24*60,2),ROUND((AG3-B3)*24*60,2)),"") -> 0.02
A4: 业务连续性风险 | B4: 45943.959 | C4: 设备离线 | D4: XDR-STA设备离线 | I4: 已闭环 | J4: 价值交付三组 | M4: XDR-STA | N4: 设备离线 | O4: 高 | S4: 谢华圣 | T4: 未知 | V4: 未知 | W4: 设备离线 | X4: 设备离线，请及时处理 | Z4: 服务内 (7*24H) | AC4: 45943.99 | AD4: 45943.956 | AQ4: 设备已检测到上线，自动关闭 | AY4: =VLOOKUP(E4,资产表!C:AG,31,0) -> #N/A | AZ4: =IF(A4<>"最新威胁",ROUND((B4-AD4)*24*60,2),"") -> 4.08 | BA4: =IF(A4<>"最新威胁",IF(ISBLANK(AX4),IF(ISBLANK(AE4),ROUND((AC4-B4)*24*60,2),ROUND((AE4-B4)*24*60,2)),ROUND((AX4-B4)*24*60,2)),"") -> 43.93 | BB4: =IF(A4<>"最新威胁",IF(ISBLANK(AX4),"",ROUND((AX4-B4)*24*60,2)),"") | BC4: =IF(A4<>"最新威胁",IF(ISBLANK(AF4),ROUND((AC4-B4)*24*60,2),ROUND((AF4-B4)*24*60,2)),"") -> 43.93 | BD4: =IF(A4<>"最新威胁",IF(ISBLANK(AG4),ROUND((AC4-B4)*24*60,2),ROUND((AG4-B4)*24*60,2)),"") -> 43.93
A5: 重大事件 | B5: 45947.364 | C5: 账号安全 | D5: 弱口令登录成功 | I5: 已闭环 | J5: 价值交付三组 | M5: XDR-STA | N5: 账号安全 | O5: 低 | S5: 郭永斌 | T5: 服务器 | V5: 低 | W5: 安全分析中台引擎 | Z5: 服务内 (7*24H) | AC5: 46028.398 | AD5: 45947.363 | AE5: 45947.375 | AF5: 45947.398 | AG5: 46028.398 | AK5: 客户反馈满意 | AQ5: 弱口令已推送修改 | AV5: 54天19时27分 | AY5: =VLOOKUP(E5,资产表!C:AG,31,0) -> #N/A | AZ5: =IF(A5<>"最新威胁",ROUND((B5-AD5)*24*60,2),"") -> 1.4 | BA5: =IF(A5<>"最新威胁",IF(ISBLANK(AX5),IF(ISBLANK(AE5),ROUND((AC5-B5)*24*60,2),ROUND((AE5-B5)*24*60,2)),ROUND((AX5-B5)*24*60,2)),"") -> 15.58 | BB5: =IF(A5<>"最新威胁",IF(ISBLANK(AX5),"",ROUND((AX5-B5)*24*60,2)),"") | BC5: =IF(A5<>"最新威胁",IF(ISBLANK(AF5),ROUND((AC5-B5)*24*60,2),ROUND((AF5-B5)*24*60,2)),"") -> 47.82 | BD5: =IF(A5<>"最新威胁",IF(ISBLANK(AG5),ROUND((AC5-B5)*24*60,2),ROUND((AG5-B5)*24*60,2)),"") -> 116687.82
A6: 重大事件 | B6: 45973.587 | C6: 脆弱性->账号安全 | D6: 弱口令登录成功 | I6: 已闭环 | J6: 价值交付三组 | M6: XDR-STA | N6: 账号安全 | O6: 低 | S6: 郭永斌 | T6: 服务器 | V6: 高 | Z6: 服务内 (7*24H) | AC6: 46028.398 | AD6: 45973.587 | AE6: 45973.591 | AF6: 45973.606 | AG6: 46028.398 | AK6: 客户反馈满意 | AQ6: 弱口令已推送修改 | AV6: 54天19时27分 | AW6: 已通告 | AX6: 45973.591 | AY6: =VLOOKUP(E6,资产表!C:AG,31,0) -> #N/A | AZ6: =IF(A6<>"最新威胁",ROUND((B6-AD6)*24*60,2),"") -> 1.22 | BA6: =IF(A6<>"最新威胁",IF(ISBLANK(AX6),IF(ISBLANK(AE6),ROUND((AC6-B6)*24*60,2),ROUND((AE6-B6)*24*60,2)),ROUND((AX6-B6)*24*60,2)),"") -> 4.62 | BB6: =IF(A6<>"最新威胁",IF(ISBLANK(AX6),"",ROUND((AX6-B6)*24*60,2)),"") -> 4.62 | BC6: =IF(A6<>"最新威胁",IF(ISBLANK(AF6),ROUND((AC6-B6)*24*60,2),ROUND((AF6-B6)*24*60,2)),"") -> 26.55 | BD6: =IF(A6<>"最新威胁",IF(ISBLANK(AG6),ROUND((AC6-B6)*24*60,2),ROUND((AG6-B6)*24*60,2)),"") -> 78926.55
A7: 重大事件 | B7: 46076.749 | C7: 应急工单->账号爆破 | D7: 主机存在暴力破解威胁 | I7: 已闭环 | J7: 价值交付三组 | M7: EDR | N7: 账号爆破 | O7: 低 | S7: 郭永斌 | T7: 服务器 | V7: 高 | W7: APEX-GPT引擎 | X7: 检测到主机存在暴力破解威胁 | Z7: 服务内 (7*24H) | AC7: 46083.413 | AD7: 46076.747 | AE7: 46076.753 | AF7: 46083.413 | AG7: 46083.413 | AK7: 客户反馈满意 | AQ7: 已推送服务群处置/确认，后续持续观察 | AV7: 0天19时10分 | AW7: 已通告 | AX7: 46076.752 | AY7: =VLOOKUP(E7,资产表!C:AG,31,0) -> #N/A | AZ7: =IF(A7<>"最新威胁",ROUND((B7-AD7)*24*60,2),"") -> 1.83 | BA7: =IF(A7<>"最新威胁",IF(ISBLANK(AX7),IF(ISBLANK(AE7),ROUND((AC7-B7)*24*60,2),ROUND((AE7-B7)*24*60,2)),ROUND((AX7-B7)*24*60,2)),"") -> 5.47 | BB7: =IF(A7<>"最新威胁",IF(ISBLANK(AX7),"",ROUND((AX7-B7)*24*60,2)),"") -> 5.47 | BC7: =IF(A7<>"最新威胁",IF(ISBLANK(AF7),ROUND((AC7-B7)*24*60,2),ROUND((AF7-B7)*24*60,2)),"") -> 9597.07 | BD7: =IF(A7<>"最新威胁",IF(ISBLANK(AG7),ROUND((AC7-B7)*24*60,2),ROUND((AG7-B7)*24*60,2)),"") -> 9597.07
A8: 重大事件 | B8: 46077.64 | C8: 应急工单->扫描工具 | D8: 主机存在Nmap工具扫描 | I8: 已闭环 | J8: 价值交付三组 | L8: - | M8: XDR-STA | N8: 扫描工具 | O8: 低 | S8: 郭永斌 | T8: 服务器 | V8: 高 | X8: Nmap是一款网络扫描工具。命中该规则表明攻击者使用Nmap向网络发起扫描 | Z8: 服务内 (7*24H) | AC8: 46083.413 | AD8: 46077.639 | AE8: 46077.648 | AF8: 46083.413 | AG8: 46083.413 | AK8: 客户反馈满意 | AQ8: 已推送服务群处置/确认，后续持续观察 | AV8: 0天19时10分 | AW8: 已通告 | AX8: 46077.648 | AY8: =VLOOKUP(E8,资产表!C:AG,31,0) -> #N/A | AZ8: =IF(A8<>"最新威胁",ROUND((B8-AD8)*24*60,2),"") -> 1.17 | BA8: =IF(A8<>"最新威胁",IF(ISBLANK(AX8),IF(ISBLANK(AE8),ROUND((AC8-B8)*24*60,2),ROUND((AE8-B8)*24*60,2)),ROUND((AX8-B8)*24*60,2)),"") -> 11.1 | BB8: =IF(A8<>"最新威胁",IF(ISBLANK(AX8),"",ROUND((AX8-B8)*24*60,2)),"") -> 11.1 | BC8: =IF(A8<>"最新威胁",IF(ISBLANK(AF8),ROUND((AC8-B8)*24*60,2),ROUND((AF8-B8)*24*60,2)),"") -> 8313.17 | BD8: =IF(A8<>"最新威胁",IF(ISBLANK(AG8),ROUND((AC8-B8)*24*60,2),ROUND((AG8-B8)*24*60,2)),"") -> 8313.17
A9: 重大威胁 | B9: 45985.387 | C9: 外部威胁->web攻击 | D9: 主机遭受web攻击 | I9: 已闭环 | J9: 价值交付三组 | M9: AF | N9: web攻击 | O9: 低 | S9: 郭永斌 | T9: 未知 | V9: 中 | W9: 感知提升：建议推送、自定义usecase、安全分析中台引擎 | Z9: 服务内 (7*24H) | AC9: 46002.77 | AD9: 45985.386 | AE9: 45985.388 | AF9: 46002.77 | AG9: 46002.77 | AJ9: None | AK9: 客户反馈满意 | AQ9: 攻击失败，已封堵恶意地址 | AV9: 0天1时34分 | AW9: 已通告 | AX9: 45985.39 | AY9: =VLOOKUP(E9,资产表!C:AG,31,0) -> #N/A | AZ9: =IF(A9<>"最新威胁",ROUND((B9-AD9)*24*60,2),"") -> 0.48 | BA9: =IF(A9<>"最新威胁",IF(ISBLANK(AX9),IF(ISBLANK(AE9),ROUND((AC9-B9)*24*60,2),ROUND((AE9-B9)*24*60,2)),ROUND((AX9-B9)*24*60,2)),"") -> 4.88 | BB9: =IF(A9<>"最新威胁",IF(ISBLANK(AX9),"",ROUND((AX9-B9)*24*60,2)),"") -> 4.88 | BC9: =IF(A9<>"最新威胁",IF(ISBLANK(AF9),ROUND((AC9-B9)*24*60,2),ROUND((AF9-B9)*24*60,2)),"") -> 25031.8 | BD9: =IF(A9<>"最新威胁",IF(ISBLANK(AG9),ROUND((AC9-B9)*24*60,2),ROUND((AG9-B9)*24*60,2)),"") -> 25031.8
A10: 重大威胁 | B10: 45880.401 | C10: 外部威胁->web攻击 | D10: 主机遭受web攻击 | I10: 已闭环 | J10: 价值交付三组 | M10: AF | N10: web攻击 | O10: 低 | S10: 郭永斌 | T10: 服务器 | V10: 低 | W10: 安全分析中台引擎、感知提升：建议推送、自定义usecase | Z10: 服务内 (7*24H) | AC10: 45880.473 | AD10: 45880.399 | AE10: 45880.404 | AF10: 45880.473 | AG10: 45880.473 | AJ10: None | AK10: 客户反馈满意 | AQ10: 攻击失败，恶意地址已被封堵 | AV10: 0天1时44分 | AW10: 已通告 | AX10: 45880.404 | AY10: =VLOOKUP(E10,资产表!C:AG,31,0) -> #N/A | AZ10: =IF(A10<>"最新威胁",ROUND((B10-AD10)*24*60,2),"") -> 3.33 | BA10: =IF(A10<>"最新威胁",IF(ISBLANK(AX10),IF(ISBLANK(AE10),ROUND((AC10-B10)*24*60,2),ROUND((AE10-B10)*24*60,2)),ROUND((AX10-B10)*24*60,2)),"") -> 3.97 | BB10: =IF(A10<>"最新威胁",IF(ISBLANK(AX10),"",ROUND((AX10-B10)*24*60,2)),"") -> 3.97 | BC10: =IF(A10<>"最新威胁",IF(ISBLANK(AF10),ROUND((AC10-B10)*24*60,2),ROUND((AF10-B10)*24*60,2)),"") -> 103.55 | BD10: =IF(A10<>"最新威胁",IF(ISBLANK(AG10),ROUND((AC10-B10)*24*60,2),ROUND((AG10-B10)*24*60,2)),"") -> 103.55
A11: 重大威胁 | B11: 45958.731 | C11: 外部威胁->漏洞利用攻击 | D11: 主机遭受漏洞利用攻击 | I11: 已闭环 | J11: 价值交付三组 | M11: AF | N11: 漏洞利用攻击 | O11: 中 | S11: 郭永斌 | T11: 服务器 | V11: 低 | W11: 感知提升：建议推送、自定义usecase、安全分析中台引擎 | Z11: 服务内 (7*24H) | AC11: 46002.77 | AD11: 45958.731 | AE11: 45958.732 | AF11: 46002.77 | AG11: 46002.77 | AJ11: None | AK11: 客户反馈满意 | AQ11: 攻击失败，已封堵恶意地址 | AV11: 0天1时34分 | AW11: 已通告 | AX11: 45958.732 | AY11: =VLOOKUP(E11,资产表!C:AG,31,0) -> #N/A | AZ11: =IF(A11<>"最新威胁",ROUND((B11-AD11)*24*60,2),"") -> 0.2 | BA11: =IF(A11<>"最新威胁",IF(ISBLANK(AX11),IF(ISBLANK(AE11),ROUND((AC11-B11)*24*60,2),ROUND((AE11-B11)*24*60,2)),ROUND((AX11-B11)*24*60,2)),"") -> 1.77 | BB11: =IF(A11<>"最新威胁",IF(ISBLANK(AX11),"",ROUND((AX11-B11)*24*60,2)),"") -> 1.77 | BC11: =IF(A11<>"最新威胁",IF(ISBLANK(AF11),ROUND((AC11-B11)*24*60,2),ROUND((AF11-B11)*24*60,2)),"") -> 63415.5 | BD11: =IF(A11<>"最新威胁",IF(ISBLANK(AG11),ROUND((AC11-B11)*24*60,2),ROUND((AG11-B11)*24*60,2)),"") -> 63415.5
A12: 一般事件 | B12: 45870.635 | C12: 渗透框架 | D12: 主机存在感染黑客工具家族cobaltstrike | I12: 已闭环 | J12: 价值交付三组 | L12: - | M12: XDR-STA | N12: 渗透框架 | O12: 低 | S12: 郭永斌 | T12: 未知 | V12: 低 | X12: Cobalt Strike是一款基于Java编写的全平台多方协同后渗透攻击框架，也称为CS。早期版本依赖Metasploit框架，Cobalt Strike 3.0之后则是作为单独的平台使用。其支持多种通信协议，包括http、https、dns、smb等，同时集成了提权、凭据导出、端口转发、端口扫描、横向移动、Socks代理、钓鱼攻击等功能，且支持丰富的扩展插件，几乎可以覆盖APT攻击链所需的各个技术环节。木马生成方面也涵盖了大多数的平台和攻击场景，包括 PE木马、ELF木马、网页木马、Office宏病毒木马等 | Z12: 服务外 | AC12: 45881.654 | AD12: 45870.63 | AE12: 45870.635 | AF12: 45870.636 | AG12: 45870.636 | AK12: 客户反馈满意 | AQ12: 关联告警已处置，自动变更状态 | AV12: 0天0时1分 | AY12: =VLOOKUP(E12,资产表!C:AG,31,0) -> #N/A | AZ12: =IF(A12<>"最新威胁",ROUND((B12-AD12)*24*60,2),"") -> 7.87 | BA12: =IF(A12<>"最新威胁",IF(ISBLANK(AX12),IF(ISBLANK(AE12),ROUND((AC12-B12)*24*60,2),ROUND((AE12-B12)*24*60,2)),ROUND((AX12-B12)*24*60,2)),"") -> 0.1 | BB12: =IF(A12<>"最新威胁",IF(ISBLANK(AX12),"",ROUND((AX12-B12)*24*60,2)),"") | BC12: =IF(A12<>"最新威胁",IF(ISBLANK(AF12),ROUND((AC12-B12)*24*60,2),ROUND((AF12-B12)*24*60,2)),"") -> 0.95 | BD12: =IF(A12<>"最新威胁",IF(ISBLANK(AG12),ROUND((AC12-B12)*24*60,2),ROUND((AG12-B12)*24*60,2)),"") -> 0.95
A13: 一般事件 | B13: 45871.583 | C13: 渗透框架 | D13: 主机存在感染黑客工具家族cobaltstrike | I13: 已闭环 | J13: 价值交付三组 | L13: - | M13: XDR-STA | N13: 渗透框架 | O13: 低 | S13: 贺红萍 | T13: 未知 | V13: 低 | X13: Cobalt Strike是一款基于Java编写的全平台多方协同后渗透攻击框架，也称为CS。早期版本依赖Metasploit框架，Cobalt Strike 3.0之后则是作为单独的平台使用。其支持多种通信协议，包括http、https、dns、smb等，同时集成了提权、凭据导出、端口转发、端口扫描、横向移动、Socks代理、钓鱼攻击等功能，且支持丰富的扩展插件，几乎可以覆盖APT攻击链所需的各个技术环节。木马生成方面也涵盖了大多数的平台和攻击场景，包括 PE木马、ELF木马、网页木马、Office宏病毒木马等 | Z13: 服务外 | AC13: 45871.583 | AD13: 45871.576 | AE13: 45871.583 | AF13: 45871.583 | AG13: 45871.583 | AK13: 客户反馈满意 | AQ13: 关联告警已处置，自动变更状态 | AV13: 0天0时1分 | AY13: =VLOOKUP(E13,资产表!C:AG,31,0) -> #N/A | AZ13: =IF(A13<>"最新威胁",ROUND((B13-AD13)*24*60,2),"") -> 9.42 | BA13: =IF(A13<>"最新威胁",IF(ISBLANK(AX13),IF(ISBLANK(AE13),ROUND((AC13-B13)*24*60,2),ROUND((AE13-B13)*24*60,2)),ROUND((AX13-B13)*24*60,2)),"") -> 0.07 | BB13: =IF(A13<>"最新威胁",IF(ISBLANK(AX13),"",ROUND((AX13-B13)*24*60,2)),"") | BC13: =IF(A13<>"最新威胁",IF(ISBLANK(AF13),ROUND((AC13-B13)*24*60,2),ROUND((AF13-B13)*24*60,2)),"") -> 0.4 | BD13: =IF(A13<>"最新威胁",IF(ISBLANK(AG13),ROUND((AC13-B13)*24*60,2),ROUND((AG13-B13)*24*60,2)),"") -> 0.4
A14: 最新威胁 | B14: 46059.442 | C14: 未公开威胁->威胁狩猎 | D14: 勒索预防情报速递_20260206 | I14: 已通告 | J14: 价值交付三组 | N14: 威胁狩猎 | O14: 紧急 | P14: 【勒索预防情报速递_20260206】 尊敬的用户，您好，近日深信服云端安全团队，发现勒索组织面向公网发起批量扫描行为，为防止服务器被勒索加密，建议针对以下IOC在出口防火墙进行封堵处置。 【IOC详情】 160.124.152[.]167 160.124.152[.]158 156.234.94[.]193 38.173.16[.]90 156.234.209[.]38 160.124.146[.]254 156.234.33[.]66 107.149.167[.]107 156.234.33[.]72 23.235.179[.]100 43.243.191[.]225 | S14: 郭永斌 | V14: 中 | W14: 2026热点事件 | Z14: 服务外 | AC14: 46081.627 | AG14: 46081.627 | AK14: 客户反馈满意 | AQ14: 已通告 | AS14: 2026-02-28 15:03:33 | AV14: 1天23时22分 | AY14: =VLOOKUP(E14,资产表!C:AG,31,0) -> #N/A | AZ14: =IF(A14<>"最新威胁",ROUND((B14-AD14)*24*60,2),"") | BA14: =IF(A14<>"最新威胁",IF(ISBLANK(AX14),IF(ISBLANK(AE14),ROUND((AC14-B14)*24*60,2),ROUND((AE14-B14)*24*60,2)),ROUND((AX14-B14)*24*60,2)),"") | BB14: =IF(A14<>"最新威胁",IF(ISBLANK(AX14),"",ROUND((AX14-B14)*24*60,2)),"") | BC14: =IF(A14<>"最新威胁",IF(ISBLANK(AF14),ROUND((AC14-B14)*24*60,2),ROUND((AF14-B14)*24*60,2)),"") | BD14: =IF(A14<>"最新威胁",IF(ISBLANK(AG14),ROUND((AC14-B14)*24*60,2),ROUND((AG14-B14)*24*60,2)),"")
A15: 最新威胁 | B15: 46059.602 | C15: 未公开威胁->半月刊安全通告 | D15: 1月份（下半月刊）安全通告_2026 | I15: 已通告 | J15: 价值交付三组 | N15: 半月刊安全通告 | O15: 紧急 | P15: 通告涵盖1月份（下半月刊）新增安全漏洞和安全事件的分析等。整理的具体内容包含以下几个方面： 一、 网络安全政策法律动态 （一）国内政策热点 1、国务院办公厅印发《政务移动互联网应用程序规范化管理办法》 2、2026年度第一批网络安全国家标准需求发布 （二）国际政策热点 1、美国陆军部长计划在多个军事基地停用NIPRNet 2、欧盟启动全球CVE分配系统，强化数字主权 3、欧盟委员会提议修订《网络安全法案》（《网络安全法案2.0》） 4、爱尔兰拟立法为警方使用间谍软件确立法律基础 二、安全热点时事资讯 （一）国内安全事件 1、入侵网站盗数据、跨境牟利触法网！两名犯罪嫌疑人被云南网警抓获 2、工程师以技术手段窃取赌博网站184万余名中国公民个人信息 3、B站涌现带毒软件传播新手段，供应链攻击威胁加剧 （二） 国际安全事件 1、美国某头部银行被植入键盘记录器，潜伏窃取20万登录凭证 2、伊朗国家电视台的信号被劫持，播放反政府视频煽动暴乱 3、比利时AZ Monica医院遭网络攻击，服务器被迫关闭，手术全部取消 4、麦当劳印度公司遭勒索组织攻击，861GB核心运营与财务数据被窃取 5、苹果第二大代工厂立讯精密疑遭勒索攻击，机密数据外泄 6、耐克遭勒索组织攻击，产品开发、制造运营等1.4TB核心数据被窃取 三、安全风险通告 （一）Oracle WebLogic Server Proxy Plug-in身份认证绕过漏洞(CVE-2026-21962) （二）Microsoft Office 安全功能绕过漏洞(CVE-2026-21509) 四、1月份CNVD漏洞收录情况 （一） 漏洞分类统计 （二） 漏洞被关注情况 （三） 漏洞趋势 附录：1月份重要漏洞信息汇总 | S15: 郭永斌 | V15: 中 | W15: 2026热点事件 | Z15: 服务外 | AC15: 46081.627 | AG15: 46081.627 | AK15: 客户反馈满意 | AQ15: 已通告 | AS15: 2026-02-28 15:03:33 | AV15: 1天23时22分 | AY15: =VLOOKUP(E15,资产表!C:AG,31,0) -> #N/A | AZ15: =IF(A15<>"最新威胁",ROUND((B15-AD15)*24*60,2),"") | BA15: =IF(A15<>"最新威胁",IF(ISBLANK(AX15),IF(ISBLANK(AE15),ROUND((AC15-B15)*24*60,2),ROUND((AE15-B15)*24*60,2)),ROUND((AX15-B15)*24*60,2)),"") | BB15: =IF(A15<>"最新威胁",IF(ISBLANK(AX15),"",ROUND((AX15-B15)*24*60,2)),"") | BC15: =IF(A15<>"最新威胁",IF(ISBLANK(AF15),ROUND((AC15-B15)*24*60,2),ROUND((AF15-B15)*24*60,2)),"") | BD15: =IF(A15<>"最新威胁",IF(ISBLANK(AG15),ROUND((AC15-B15)*24*60,2),ROUND((AG15-B15)*24*60,2)),"")
A16: 最新威胁 | B16: 46079.653 | C16: 未公开威胁->威胁狩猎 | D16: 勒索预防情报速递_20260226 | I16: 已通告 | J16: 价值交付三组 | N16: 威胁狩猎 | O16: 紧急 | P16: 【勒索预防情报速递_20260226】 尊敬的用户，您好，近日深信服云端安全团队，发现勒索组织面向公网发起批量扫描行为，为防止服务器被勒索加密，建议针对以下IOC在出口防火墙进行封堵处置。 23.235.169[.]66 23.235.173[.]26 23.226.58[.]225 156.234.92[.]161 156.234.94[.]222 43.249.175[.]66 43.249.172[.]97 156.234.94[.]219 23.235.163[.]205 156.234.94[.]210 156.234.56[.]34 23.235.172[.]2 156.234.254[.]135 156.234.121[.]161 23.235.172[.]24 23.235.182[.]100 23.235.163[.]33 156.234.94[.]201 156.234.247[.]110 23.226.52[.]135 103.37.2[.]10 23.226.52[.]130 156.234.21[.]196 | S16: 郭永斌 | V16: 中 | W16: 2026热点事件 | Z16: 服务外 | AC16: 46081.627 | AG16: 46081.627 | AK16: 客户反馈满意 | AQ16: 已通告 | AS16: 2026-02-28 15:03:33 | AV16: 1天23时22分 | AY16: =VLOOKUP(E16,资产表!C:AG,31,0) -> #N/A | AZ16: =IF(A16<>"最新威胁",ROUND((B16-AD16)*24*60,2),"") | BA16: =IF(A16<>"最新威胁",IF(ISBLANK(AX16),IF(ISBLANK(AE16),ROUND((AC16-B16)*24*60,2),ROUND((AE16-B16)*24*60,2)),ROUND((AX16-B16)*24*60,2)),"") | BB16: =IF(A16<>"最新威胁",IF(ISBLANK(AX16),"",ROUND((AX16-B16)*24*60,2)),"") | BC16: =IF(A16<>"最新威胁",IF(ISBLANK(AF16),ROUND((AC16-B16)*24*60,2),ROUND((AF16-B16)*24*60,2)),"") | BD16: =IF(A16<>"最新威胁",IF(ISBLANK(AG16),ROUND((AC16-B16)*24*60,2),ROUND((AG16-B16)*24*60,2)),"")
A17: 最新威胁 | B17: 46086.414 | C17: 未公开威胁->半月刊安全通告 | D17: 2月份（月刊）安全通告_2026 | I17: 已通告 | J17: 价值交付三组 | N17: 半月刊安全通告 | O17: 紧急 | P17: 通告涵盖2月份（月刊）新增安全漏洞和安全事件的分析等。整理的具体内容包含以下几个方面： 一、 网络安全政策法律动态 （一）国内政策热点 1、工信部等八部门联合印发《汽车数据出境安全指引（2026版）》 2、网安标委下达7项网络安全推荐性国家标准计划 3、网安标委发布《网络安全标准实践指南——网络数据标签标识技术要求》 4、3项网络安全国家标准获批发布 （二）国际政策热点 1、印度发布《军事量子任务政策框架》 2、法国发布《国家网络安全战略（2026-2030）》 3、白宫网络总监办公室制定AI安全政策框架 二、安全热点时事资讯 （一）国内安全事件 1、内容安全失守代价惨重：快手平台因未处置违法信息被罚1.19亿元 2、第三方平台违规存储，导致12306账号内惊现“陌生乘客”且无法删除 3、重庆某企业未履行网络安全保护义务，企业负责人被约谈 4、滥用技术参与黑产犯罪的警示：三名大厂高薪员工兼职破解系统被抓 （二） 国际安全事件 1、网络武器库泄露启示录：Exploit Pack事件敲响企业供应链安全警钟 2、因索要赎金遭拒，黑客组织公开哈佛、宾大百万条窃取的个人信息 3、Step Finance 称高管设备遭入侵，致 4000 万美元加密货币被盗 4、支付命脉遭掐断：BridgePay勒索攻击致全美数千商户业务瘫痪 5、六百万用户数据遭窃：荷兰运营商Odido数据泄露事件剖析 6、AI代理成新攻击面：OpenClaw框架遭大规模利用，超三万实例沦陷 7、支付页面遭前端劫持：某全球零售巨头电商遭遇“二次下单”攻击 三、安全风险通告 （一）n8n 表达式沙箱逃逸导致远程代码执行漏洞(CVE-2026-25049) 四、微软安全通告 （一） 漏洞概要 （二） 漏洞数据分析 （三） 重要漏洞分析 五、2月份CNVD漏洞收录情况 附录：2月份重要漏洞信息汇总 | S17: 郭永斌 | V17: 中 | W17: 2026热点事件 | Z17: 服务外 | AC17: 46086.437 | AG17: 46086.437 | AK17: 客户反馈满意 | AQ17: 已通告 | AS17: 2026-03-05 10:29:09 | AV17: 1天8时32分 | AY17: =VLOOKUP(E17,资产表!C:AG,31,0) -> #N/A | AZ17: =IF(A17<>"最新威胁",ROUND((B17-AD17)*24*60,2),"") | BA17: =IF(A17<>"最新威胁",IF(ISBLANK(AX17),IF(ISBLANK(AE17),ROUND((AC17-B17)*24*60,2),ROUND((AE17-B17)*24*60,2)),ROUND((AX17-B17)*24*60,2)),"") | BB17: =IF(A17<>"最新威胁",IF(ISBLANK(AX17),"",ROUND((AX17-B17)*24*60,2)),"") | BC17: =IF(A17<>"最新威胁",IF(ISBLANK(AF17),ROUND((AC17-B17)*24*60,2),ROUND((AF17-B17)*24*60,2)),"") | BD17: =IF(A17<>"最新威胁",IF(ISBLANK(AG17),ROUND((AC17-B17)*24*60,2),ROUND((AG17-B17)*24*60,2)),"")
A18: 一般事件 | B18: 46090.536 | C18: 内部威胁->异常操作 | D18: 主机存在SQL server数据库xp_dirtree外带数据攻击 | I18: 已闭环 | J18: 价值交付三组 | L18: - | M18: XDR-STA | N18: 异常操作 | O18: 低 | S18: 郭永斌 | T18: 终端 | V18: 高 | X18: 检测到SQL server数据库尝试进行外带数据攻击 | Z18: 服务内 (7*24H) | AC18: 46097.402 | AD18: 46090.535 | AE18: 46090.54 | AF18: 46097.402 | AG18: 46097.402 | AK18: 客户反馈满意 | AQ18: 已推送处置确认，后续继续观察 | AV18: 0天1时15分 | AW18: 已通告 | AX18: 46090.54 | AY18: =VLOOKUP(E18,资产表!C:AG,31,0) -> #N/A | AZ18: =IF(A18<>"最新威胁",ROUND((B18-AD18)*24*60,2),"") -> 1.62 | BA18: =IF(A18<>"最新威胁",IF(ISBLANK(AX18),IF(ISBLANK(AE18),ROUND((AC18-B18)*24*60,2),ROUND((AE18-B18)*24*60,2)),ROUND((AX18-B18)*24*60,2)),"") -> 5.53 | BB18: =IF(A18<>"最新威胁",IF(ISBLANK(AX18),"",ROUND((AX18-B18)*24*60,2)),"") -> 5.53 | BC18: =IF(A18<>"最新威胁",IF(ISBLANK(AF18),ROUND((AC18-B18)*24*60,2),ROUND((AF18-B18)*24*60,2)),"") -> 9886.08 | BD18: =IF(A18<>"最新威胁",IF(ISBLANK(AG18),ROUND((AC18-B18)*24*60,2),ROUND((AG18-B18)*24*60,2)),"") -> 9886.08
A19: 最新威胁 | B19: 46091.681 | C19: 未公开威胁->威胁狩猎 | D19: OpenClaw 安全性风险全链路分析及提示 | I19: 已通告 | J19: 价值交付三组 | N19: 威胁狩猎 | O19: 紧急 | P19: 【深信服-紧急事件通告】 OpenClaw 安全性风险全链路分析及提示 【OpenClaw 介绍】 OpenClaw（前身为 Clawdbot、Moltbot）是 2025 年 11 月上线的开源 AI Agent 框架，该项目被开发者定义为“真正可以执行任务的 AI”，以惊人速度成为 GitHub 历史上增长最快的现象级项目之一，上线以来累计超过 200,000 颗星。然而，其爆炸式增长暴露出严重的安全问题，漏洞数量之多、影响之广，在 AI 工具领域尚属罕见。 【OpenClaw 漏洞风险】 随着 OpenClaw 的广泛部署，一系列安全漏洞被陆续发现并分配了 CVE 编号。 已披露漏洞统计： 1、总计80余个CVE漏洞：截至2026年3月初，已披露80余个OpenClaw相关CVE漏洞 2、3个存在公开利用代码：可实现远程代码执行 3、修复进度：截至2026年2月26日发布的v2026.2.26版本，已修复超过40个漏洞 【加固建议】 OpenClaw可访问用户文件系统、执行Shell命令、调用各类第三方服务凭据，一旦被攻击者控制，将导致用户数字权限完全泄露。在企业环境中，单个被入侵实例可成为内网横向移动跳板，引发核心数据窃取、关键系统受控等严重安全事件，对于个人用户来说，隐私信息存在被窃取风险。 对企业用户的建议： 1、紧急处置与基础防护 （一）漏洞闭环与凭据管理 （二）网络层面防护 （三）认证与权限管控 2、长效安全管控 （一）供应链与插件管理 （二）监控与审计机制 （三）企业政策与流程管控 | S19: 郭永斌 | V19: 中 | W19: 2026热点事件 | Z19: 服务外 | AC19: 46098.446 | AG19: 46098.446 | AK19: 客户反馈满意 | AQ19: 已通告 | AS19: 2026-03-17 10:42:17 | AV19: 6天18时22分 | AY19: =VLOOKUP(E19,资产表!C:AG,31,0) -> #N/A | AZ19: =IF(A19<>"最新威胁",ROUND((B19-AD19)*24*60,2),"") | BA19: =IF(A19<>"最新威胁",IF(ISBLANK(AX19),IF(ISBLANK(AE19),ROUND((AC19-B19)*24*60,2),ROUND((AE19-B19)*24*60,2)),ROUND((AX19-B19)*24*60,2)),"") | BB19: =IF(A19<>"最新威胁",IF(ISBLANK(AX19),"",ROUND((AX19-B19)*24*60,2)),"") | BC19: =IF(A19<>"最新威胁",IF(ISBLANK(AF19),ROUND((AC19-B19)*24*60,2),ROUND((AF19-B19)*24*60,2)),"") | BD19: =IF(A19<>"最新威胁",IF(ISBLANK(AG19),ROUND((AC19-B19)*24*60,2),ROUND((AG19-B19)*24*60,2)),"")
A20: 最新威胁 | B20: 46094.604 | C20: 未公开威胁->微软补丁日安全通告 | D20: 微软补丁日安全通告|3月份_2026 | I20: 已通告 | J20: 价值交付三组 | N20: 微软补丁日安全通告 | O20: 紧急 | P20: 【漏洞详情】 【SQL Server特权提升漏洞 CVE-2026-21262】 Microsoft SQL Server是微软推出的关系型数据库管理系统，为企业级应用提供数据存储、查询、事务处理与权限管理等核心服务，广泛应用于各类业务系统、后台服务与数据平台，负责处理结构化数据、保障数据一致性与访问安全。 其中存在权限提升漏洞，攻击者可以利用该漏洞在目标系统获取更高权限。经过评估，该漏洞危害较大，我们建议用户及时更新微软安全补丁。 【.NET 拒绝服务漏洞 CVE-2026-26127】 .NET 是微软推出的跨平台开发框架，为各类应用提供统一的运行时环境、基础类库与安全机制，广泛用于构建 Web 服务、桌面应用与云原生程序，保障应用的兼容性、安全性与运行效率。 其中存在拒绝服务漏洞，攻击者可利用该漏洞通过网络向基于 .NET 的应用发送特制请求，导致应用崩溃、服务不可用。经过评估，该漏洞危害较大，我们建议用户及时更新微软安全补丁。 官方解决方案： 微软官方已更新受影响软件的安全补丁，用户可根据不同系统版本下载安装对应的安全补丁，安全更新链接如下： 1、https://msrc.microsoft.com/update-guide/vulnerability/CVE-2026-21262 2、https://msrc.microsoft.com/update-guide/vulnerability/CVE-2026-26127 | S20: 郭永斌 | V20: 中 | W20: 2026热点事件 | Z20: 服务外 | AC20: 46094.622 | AG20: 46094.622 | AK20: 客户反馈满意 | AQ20: 已通告 | AS20: 2026-03-13 14:55:16 | AV20: 1天1时6分 | AY20: =VLOOKUP(E20,资产表!C:AG,31,0) -> #N/A | AZ20: =IF(A20<>"最新威胁",ROUND((B20-AD20)*24*60,2),"") | BA20: =IF(A20<>"最新威胁",IF(ISBLANK(AX20),IF(ISBLANK(AE20),ROUND((AC20-B20)*24*60,2),ROUND((AE20-B20)*24*60,2)),ROUND((AX20-B20)*24*60,2)),"") | BB20: =IF(A20<>"最新威胁",IF(ISBLANK(AX20),"",ROUND((AX20-B20)*24*60,2)),"") | BC20: =IF(A20<>"最新威胁",IF(ISBLANK(AF20),ROUND((AC20-B20)*24*60,2),ROUND((AF20-B20)*24*60,2)),"") | BD20: =IF(A20<>"最新威胁",IF(ISBLANK(AG20),ROUND((AC20-B20)*24*60,2),ROUND((AG20-B20)*24*60,2)),"")
